Workbook

Sheet サマリ
A1: Change Intelligence 本番化 費用サマリ（円）
A2: すべて他シートの数式参照。前提シートの黄色セルを変えると更新されます。
B4: A. AWS + AuraDB | C4: B. AWS + Neptune | D4: C. GCP + AuraDB | E4: D. GCP + Spanner Graph | F4: 備考
A5: 開発費（5 か月, 人件費 + クラウド等） | B5: =開発費_月別!H35 -> 32544275 | C5: =開発費_月別!H36 -> 33094275 | D5: =開発費_月別!H37 -> 32116775 | E5: =開発費_月別!H38 -> 34041775 | F5: 開発費_月別 シナリオ別合計
A6: 開発費 予備費込み（推奨予算） | B6: =開発費_月別!H41 -> 37425916 | C6: =開発費_月別!H42 -> 38058416 | D6: =開発費_月別!H43 -> 36934291 | E6: =開発費_月別!H44 -> 39148041 | F6: 予備費率は開発費_月別で変更可
A7: クラウド運用費 年 1（小規模, 本番 + ステージング） | B7: =運用費_AWS_月別!AQ26 -> 892176.16 | C7: =運用費_AWS_月別!AQ26 -> 892176.16 | D7: =運用費_GCP_月別!AQ25 -> 802344.96 | E7: =運用費_GCP_月別!AQ25 -> 802344.96 | F7: B・D は Aura 行を代替 DB に読み替え（差額は前提の単価から試算: Neptune ≒ 同等, Spanner ≒ −$100/月）
A8: クラウド運用費 年 2（中規模） | B8: =運用費_AWS_月別!AR26 -> 2935641.3 | C8: =運用費_AWS_月別!AR26 -> 2935641.3 | D8: =運用費_GCP_月別!AR25 -> 2809506.2 | E8: =運用費_GCP_月別!AR25 -> 2809506.2
A9: クラウド運用費 年 3（中規模） | B9: =運用費_AWS_月別!AS26 -> 2935641.3 | C9: =運用費_AWS_月別!AS26 -> 2935641.3 | D9: =運用費_GCP_月別!AS25 -> 2809506.2 | E9: =運用費_GCP_月別!AS25 -> 2809506.2
A10: 保守・運用 人件費 3 年 | B10: =運用費_AWS_月別!AT27 -> 28980000 | C10: =運用費_AWS_月別!AT27 -> 28980000 | D10: =運用費_GCP_月別!AT26 -> 28980000 | E10: =運用費_GCP_月別!AT26 -> 28980000 | F10: 0.7 人月/月 × 36 か月。AI 活用で削減を狙う部分
A11: 3 年 TCO（開発 + クラウド 3 年 + 人件費 3 年） | B11: =B5+B7+B8+B9+B10 -> 68287734 | C11: =C5+C7+C8+C9+C10 -> 68837734 | D11: =D5+D7+D8+D9+D10 -> 67518132 | E11: =E5+E7+E8+E9+E10 -> 69443132 | F11: 予備費は含まない
A13: 月額の目安（小規模 = 1 か月目 / 中規模 = 13 か月目）
B14: AWS 小規模 | C14: AWS 中規模 | D14: GCP 小規模 | E14: GCP 中規模 | F14: 備考
A15: 本番クラウド費（USD） | B15: =運用費_AWS_月別!G18 -> 353.7953 | C15: =運用費_AWS_月別!S18 -> 1306.9656 | D15: =運用費_GCP_月別!G17 -> 318.148 | E15: =運用費_GCP_月別!S17 -> 1256.912 | F15: 本番小計
A16: ステージング（USD） | B16: =運用費_AWS_月別!G23 -> 141.85812 | C16: =運用費_AWS_月別!S23 -> 323.94624 | D16: =運用費_GCP_月別!G22 -> 127.5992 | E16: =運用費_GCP_月別!S22 -> 303.9248
A17: クラウド合計（円） | B17: =運用費_AWS_月別!G26 -> 74348.013 | C17: =運用費_AWS_月別!S26 -> 244636.78 | D17: =運用費_GCP_月別!G25 -> 66862.08 | E17: =運用費_GCP_月別!S25 -> 234125.52 | F17: 本番 + ステージング
A18: 保守・運用 人件費（円） | B18: =運用費_AWS_月別!G27 -> 805000 | C18: =運用費_AWS_月別!S27 -> 805000 | D18: =運用費_GCP_月別!G26 -> 805000 | E18: =運用費_GCP_月別!S26 -> 805000
A19: 月額 総合計（円） | B19: =運用費_AWS_月別!G28 -> 879348.01 | C19: =運用費_AWS_月別!S28 -> 1049636.8 | D19: =運用費_GCP_月別!G27 -> 871862.08 | E19: =運用費_GCP_月別!S27 -> 1039125.5
A21: 注記
A22: ・クラウド料金は 2026-10 時点の米国リージョン公開価格（USD）。為替 150 円/USD は仮置き。
A23: ・人月単価・稼働は仮置き。貴社の体制・単価に置き換えること（前提シート）。
A24: ・AI 行は『AI 活用 第 1 弾』の試算（小規模 $32/月、中規模 $300/月）。詳細は docs/cloud-selection-cost-and-ai-plan.md §5.6。
A25: ・閉域接続（PrivateLink / Private Service Connect）が必須の場合、Aura は Enterprise ティア（個別見積, Professional の 2〜3 倍目安）になる。

Sheet 前提
A1: Change Intelligence 本番化 費用モデル — 前提（黄色・青字のセルを編集すると全シートが再計算されます）
A2: 作成 2026-10-06。クラウド料金は 2026-10 時点の公開価格（米国リージョン, USD）。人月単価は仮置き。
A4: 項目 | B4: 値 | C4: 単位 | D4: 備考
A5: 為替レート | B5: 150 | C5: 円/USD | D5: 仮置き。予算時点のレートに置き換える
A6: 1 か月の稼働時間 | B6: 730 | C6: 時間/月 | D6: 24 時間 × 365 日 ÷ 12
A7: 開発期間 | B7: 5 | C7: か月 | D7: 要件 1.0 / 基本設計 0.5 / 実装 2.5 / テスト・移行 1.0
A8: 運用: 中規模へ切り替わる月（運用開始からの通算月） | B8: 13 | C8: か月目 | D8: 初年度は小規模、2 年目から中規模の想定
A9: ステージング環境の規模（本番比） | B9: 0.4 | C9: 倍 | D9: コンピュート・LB・ログを本番の 40% とみなす
A10: 保守・運用の人件費（人月/月） | B10: 0.7 | C10: 人月/月 | D10: アプリ保守 0.5 + インフラ 0.2
A11: 保守・運用の人月単価 | B11: 1150000 | C11: 円/人月 | D11: SE と SRE の平均
A13: 開発体制（共通）
A14: 役割 | B14: 人月単価（円） | C14: 稼働（人） | D14: 備考
A15: PM | B15: 1500000 | C15: 0.5 | D15: 国内 SIer / 社内開発の一般的な水準を仮置き
A16: テックリード / アーキテクト | B16: 1400000 | C16: 1 | D16: 国内 SIer / 社内開発の一般的な水準を仮置き
A17: バックエンド（Collector・分析） | B17: 1100000 | C17: 2 | D17: 国内 SIer / 社内開発の一般的な水準を仮置き
A18: フロントエンド | B18: 1000000 | C18: 1 | D18: 国内 SIer / 社内開発の一般的な水準を仮置き
A19: インフラ / SRE | B19: 1200000 | C19: 0.5 | D19: 国内 SIer / 社内開発の一般的な水準を仮置き
A20: QA / テスト | B20: 900000 | C20: 0.5 | D20: 国内 SIer / 社内開発の一般的な水準を仮置き
A21: 合計 | B21: =SUMPRODUCT(B15:B20,C15:C20) -> 6400000 | C21: =SUM(C15:C20) -> 5.5 | D21: B 列 = 月額人件費（円）, C 列 = 人数
A23: シナリオ別の追加工数（人月）
A24: シナリオ | B24: 追加人月 | C24: 発生月（開発 M） | D24: 備考
A25: B. AWS + Neptune: Graph 層の書き換え | B25: 0.5 | C25: 3 | D25: 制約・インデックスの置き換え、Bolt のみ、APOC 非対応の確認
A26: C/D. GCP: Cloud Run / IAP による構築簡略化 | B26: -0.3 | C26: 2 | D26: ECS + ALB + Cognito より構築が速い分のマイナス
A27: D. GCP + Spanner Graph: Graph 層の書き直し（M2） | B27: 0.75 | C27: 2 | D27: スキーマ設計 + CREATE PROPERTY GRAPH
A28: D. GCP + Spanner Graph: Graph 層の書き直し（M3） | B28: 1 | C28: 3 | D28: GQL への書き換え、seed / Resolve の再実装
A29: 追加工数の単価（円/人月） | B29: 1100000 | D29: バックエンド SE 単価
A31: 開発期間中のクラウド・ツール（USD/月）
A32: 項目 | B32: AWS | C32: GCP | D32: 備考
A33: 開発・ステージング環境（コンテナ・LB・ログ） | B33: 400 | C33: 270 | D33: 2 環境分。夜間停止で削減可
A34: Graph DB（開発用 AuraDB Professional 1GB） | B34: 65.7 | C34: 65.7 | D34: $65/GB/月, 最小 1GB。https://neo4j.com/pricing
A35: LLM API（開発・評価） | B35: 130 | C35: 130 | D35: Sonnet 5.5 中心。約 2 万円/月
A36: CI/CD・リポジトリ・監視 SaaS | B36: 130 | C36: 130 | D36: GitHub 等。約 2 万円/月
A38: 運用: クラウド単価（USD）
A39: 項目 | B39: 単価 | C39: 単位 | D39: 出典 / 備考
A40: AWS Fargate vCPU | B40: 0.04048 | C40: USD/vCPU 時 | D40: https://aws.amazon.com/fargate/pricing（US East, Linux x86）
A41: AWS Fargate メモリ | B41: 0.004445 | C41: USD/GB 時 | D41: 同上
A42: AWS ALB 固定 | B42: 0.0225 | C42: USD/時 | D42: https://aws.amazon.com/elasticloadbalancing/pricing。LCU は別行
A43: AWS NAT Gateway | B43: 0.045 | C43: USD/時 | D43: データ処理料は別途。VPC エンドポイントで回避可
A44: GCP Cloud Run vCPU（常時割当） | B44: 1.8e-05 | C44: USD/vCPU 秒 | D44: https://cloud.google.com/run/pricing（Tier 1）
A45: GCP Cloud Run メモリ（常時割当） | B45: 2e-06 | C45: USD/GiB 秒 | D45: 同上
...

Sheet 開発費_月別
A1: 開発期間中の費用 — 月別・項目別（円）
A2: 人件費 = 人月単価 × 稼働（前提シート）。クラウド費 = USD × 為替。シナリオ別の合計は最下段。
A4: 区分 | B4: 項目 | C4: M1 要件定義 | D4: M2 基本設計 | E4: M3 実装 | F4: M4 実装 | G4: M5 テスト・移行 | H4: 合計（円） | I4: 備考
A5: 人件費（共通）
A6: 人件費 | B6: PM | C6: =前提!$B$15*前提!$C$15 -> 750000 | D6: =前提!$B$15*前提!$C$15 -> 750000 | E6: =前提!$B$15*前提!$C$15 -> 750000 | F6: =前提!$B$15*前提!$C$15 -> 750000 | G6: =前提!$B$15*前提!$C$15 -> 750000 | H6: =SUM(C6:G6) -> 3750000 | I6: 全期間で同じ稼働を仮定
A7: 人件費 | B7: テックリード / アーキテクト | C7: =前提!$B$16*前提!$C$16 -> 1400000 | D7: =前提!$B$16*前提!$C$16 -> 1400000 | E7: =前提!$B$16*前提!$C$16 -> 1400000 | F7: =前提!$B$16*前提!$C$16 -> 1400000 | G7: =前提!$B$16*前提!$C$16 -> 1400000 | H7: =SUM(C7:G7) -> 7000000 | I7: 全期間で同じ稼働を仮定
A8: 人件費 | B8: バックエンド（Collector・分析） | C8: =前提!$B$17*前提!$C$17 -> 2200000 | D8: =前提!$B$17*前提!$C$17 -> 2200000 | E8: =前提!$B$17*前提!$C$17 -> 2200000 | F8: =前提!$B$17*前提!$C$17 -> 2200000 | G8: =前提!$B$17*前提!$C$17 -> 2200000 | H8: =SUM(C8:G8) -> 11000000 | I8: 全期間で同じ稼働を仮定
A9: 人件費 | B9: フロントエンド | C9: =前提!$B$18*前提!$C$18 -> 1000000 | D9: =前提!$B$18*前提!$C$18 -> 1000000 | E9: =前提!$B$18*前提!$C$18 -> 1000000 | F9: =前提!$B$18*前提!$C$18 -> 1000000 | G9: =前提!$B$18*前提!$C$18 -> 1000000 | H9: =SUM(C9:G9) -> 5000000 | I9: 全期間で同じ稼働を仮定
A10: 人件費 | B10: インフラ / SRE | C10: =前提!$B$19*前提!$C$19 -> 600000 | D10: =前提!$B$19*前提!$C$19 -> 600000 | E10: =前提!$B$19*前提!$C$19 -> 600000 | F10: =前提!$B$19*前提!$C$19 -> 600000 | G10: =前提!$B$19*前提!$C$19 -> 600000 | H10: =SUM(C10:G10) -> 3000000 | I10: 全期間で同じ稼働を仮定
A11: 人件費 | B11: QA / テスト | C11: =前提!$B$20*前提!$C$20 -> 450000 | D11: =前提!$B$20*前提!$C$20 -> 450000 | E11: =前提!$B$20*前提!$C$20 -> 450000 | F11: =前提!$B$20*前提!$C$20 -> 450000 | G11: =前提!$B$20*前提!$C$20 -> 450000 | H11: =SUM(C11:G11) -> 2250000 | I11: 全期間で同じ稼働を仮定
B12: 人件費 小計 | C12: =SUM(C6:C11) -> 6400000 | D12: =SUM(D6:D11) -> 6400000 | E12: =SUM(E6:E11) -> 6400000 | F12: =SUM(F6:F11) -> 6400000 | G12: =SUM(G6:G11) -> 6400000 | H12: =SUM(H6:H11) -> 32000000
A14: クラウド・ツール（AWS）
A15: クラウド等 | B15: 開発・ステージング環境（コンテナ・LB・ログ） | C15: =前提!$B$33*前提!$B$5 -> 60000 | D15: =前提!$B$33*前提!$B$5 -> 60000 | E15: =前提!$B$33*前提!$B$5 -> 60000 | F15: =前提!$B$33*前提!$B$5 -> 60000 | G15: =前提!$B$33*前提!$B$5 -> 60000 | H15: =SUM(C15:G15) -> 300000 | I15: 2 環境分。夜間停止で削減可
A16: クラウド等 | B16: Graph DB（開発用 AuraDB Professional 1GB） | C16: =前提!$B$34*前提!$B$5 -> 9855 | D16: =前提!$B$34*前提!$B$5 -> 9855 | E16: =前提!$B$34*前提!$B$5 -> 9855 | F16: =前提!$B$34*前提!$B$5 -> 9855 | G16: =前提!$B$34*前提!$B$5 -> 9855 | H16: =SUM(C16:G16) -> 49275 | I16: $65/GB/月, 最小 1GB。https://neo4j.com/pricing
A17: クラウド等 | B17: LLM API（開発・評価） | C17: =前提!$B$35*前提!$B$5 -> 19500 | D17: =前提!$B$35*前提!$B$5 -> 19500 | E17: =前提!$B$35*前提!$B$5 -> 19500 | F17: =前提!$B$35*前提!$B$5 -> 19500 | G17: =前提!$B$35*前提!$B$5 -> 19500 | H17: =SUM(C17:G17) -> 97500 | I17: Sonnet 5.5 中心。約 2 万円/月
A18: クラウド等 | B18: CI/CD・リポジトリ・監視 SaaS | C18: =前提!$B$36*前提!$B$5 -> 19500 | D18: =前提!$B$36*前提!$B$5 -> 19500 | E18: =前提!$B$36*前提!$B$5 -> 19500 | F18: =前提!$B$36*前提!$B$5 -> 19500 | G18: =前提!$B$36*前提!$B$5 -> 19500 | H18: =SUM(C18:G18) -> 97500 | I18: GitHub 等。約 2 万円/月
B19: クラウド・ツール（AWS） 小計 | C19: =SUM(C15:C18) -> 108855 | D19: =SUM(D15:D18) -> 108855 | E19: =SUM(E15:E18) -> 108855 | F19: =SUM(F15:F18) -> 108855 | G19: =SUM(G15:G18) -> 108855 | H19: =SUM(H15:H18) -> 544275
A21: クラウド・ツール（GCP）
A22: クラウド等 | B22: 開発・ステージング環境（コンテナ・LB・ログ） | C22: =前提!$C$33*前提!$B$5 -> 40500 | D22: =前提!$C$33*前提!$B$5 -> 40500 | E22: =前提!$C$33*前提!$B$5 -> 40500 | F22: =前提!$C$33*前提!$B$5 -> 40500 | G22: =前提!$C$33*前提!$B$5 -> 40500 | H22: =SUM(C22:G22) -> 202500 | I22: 2 環境分。夜間停止で削減可
A23: クラウド等 | B23: Graph DB（開発用 AuraDB Professional 1GB） | C23: =前提!$C$34*前提!$B$5 -> 9855 | D23: =前提!$C$34*前提!$B$5 -> 9855 | E23: =前提!$C$34*前提!$B$5 -> 9855 | F23: =前提!$C$34*前提!$B$5 -> 9855 | G23: =前提!$C$34*前提!$B$5 -> 9855 | H23: =SUM(C23:G23) -> 49275 | I23: $65/GB/月, 最小 1GB。https://neo4j.com/pricing
A24: クラウド等 | B24: LLM API（開発・評価） | C24: =前提!$C$35*前提!$B$5 -> 19500 | D24: =前提!$C$35*前提!$B$5 -> 19500 | E24: =前提!$C$35*前提!$B$5 -> 19500 | F24: =前提!$C$35*前提!$B$5 -> 19500 | G24: =前提!$C$35*前提!$B$5 -> 19500 | H24: =SUM(C24:G24) -> 97500 | I24: Sonnet 5.5 中心。約 2 万円/月
A25: クラウド等 | B25: CI/CD・リポジトリ・監視 SaaS | C25: =前提!$C$36*前提!$B$5 -> 19500 | D25: =前提!$C$36*前提!$B$5 -> 19500 | E25: =前提!$C$36*前提!$B$5 -> 19500 | F25: =前提!$C$36*前提!$B$5 -> 19500 | G25: =前提!$C$36*前提!$B$5 -> 19500 | H25: =SUM(C25:G25) -> 97500 | I25: GitHub 等。約 2 万円/月
B26: クラウド・ツール（GCP） 小計 | C26: =SUM(C22:C25) -> 89355 | D26: =SUM(D22:D25) -> 89355 | E26: =SUM(E22:E25) -> 89355 | F26: =SUM(F22:F25) -> 89355 | G26: =SUM(G22:G25) -> 89355 | H26: =SUM(H22:H25) -> 446775
A28: シナリオ別の追加工数（円）
A29: 追加工数 | B29: B. AWS + Neptune: Graph 層の書き換え | C29: =IF(前提!$C$25=1,前提!$B$25*前提!$B$29,0) -> 0 | D29: =IF(前提!$C$25=2,前提!$B$25*前提!$B$29,0) -> 0 | E29: =IF(前提!$C$25=3,前提!$B$25*前提!$B$29,0) -> 550000 | F29: =IF(前提!$C$25=4,前提!$B$25*前提!$B$29,0) -> 0 | G29: =IF(前提!$C$25=5,前提!$B$25*前提!$B$29,0) -> 0 | H29: =SUM(C29:G29) -> 550000
A30: 追加工数 | B30: C/D. GCP: Cloud Run / IAP による構築簡略化 | C30: =IF(前提!$C$26=1,前提!$B$26*前提!$B$29,0) -> 0 | D30: =IF(前提!$C$26=2,前提!$B$26*前提!$B$29,0) -> -330000 | E30: =IF(前提!$C$26=3,前提!$B$26*前提!$B$29,0) -> 0 | F30: =IF(前提!$C$26=4,前提!$B$26*前提!$B$29,0) -> 0 | G30: =IF(前提!$C$26=5,前提!$B$26*前提!$B$29,0) -> 0 | H30: =SUM(C30:G30) -> -330000
A31: 追加工数 | B31: D. GCP + Spanner Graph: Graph 層の書き直し（M2） | C31: =IF(前提!$C$27=1,前提!$B$27*前提!$B$29,0) -> 0 | D31: =IF(前提!$C$27=2,前提!$B$27*前提!$B$29,0) -> 825000 | E31: =IF(前提!$C$27=3,前提!$B$27*前提!$B$29,0) -> 0 | F31: =IF(前提!$C$27=4,前提!$B$27*前提!$B$29,0) -> 0 | G31: =IF(前提!$C$27=5,前提!$B$27*前提!$B$29,0) -> 0 | H31: =SUM(C31:G31) -> 825000
A32: 追加工数 | B32: D. GCP + Spanner Graph: Graph 層の書き直し（M3） | C32: =IF(前提!$C$28=1,前提!$B$28*前提!$B$29,0) -> 0 | D32: =IF(前提!$C$28=2,前提!$B$28*前提!$B$29,0) -> 0 | E32: =IF(前提!$C$28=3,前提!$B$28*前提!$B$29,0) -> 1100000 | F32: =IF(前提!$C$28=4,前提!$B$28*前提!$B$29,0) -> 0 | G32: =IF(前提!$C$28=5,前提!$B$28*前提!$B$29,0) -> 0 | H32: =SUM(C32:G32) -> 1100000
A34: シナリオ別 合計（円）
B35: A. AWS + AuraDB | C35: =C12+C19 -> 6508855 | D35: =D12+D19 -> 6508855 | E35: =E12+E19 -> 6508855 | F35: =F12+F19 -> 6508855 | G35: =G12+G19 -> 6508855 | H35: =H12+H19 -> 32544275
B36: B. AWS + Neptune | C36: =C12+C19+C29 -> 6508855 | D36: =D12+D19+D29 -> 6508855 | E36: =E12+E19+E29 -> 7058855 | F36: =F12+F19+F29 -> 6508855 | G36: =G12+G19+G29 -> 6508855 | H36: =H12+H19+H29 -> 33094275
B37: C. GCP + AuraDB | C37: =C12+C26+C30 -> 6489355 | D37: =D12+D26+D30 -> 6159355 | E37: =E12+E26+E30 -> 6489355 | F37: =F12+F26+F30 -> 6489355 | G37: =G12+G26+G30 -> 6489355 | H37: =H12+H26+H30 -> 32116775
B38: D. GCP + Spanner Graph | C38: =C12+C26+C30+C31+C32 -> 6489355 | D38: =D12+D26+D30+D31+D32 -> 6984355 | E38: =E12+E26+E30+E31+E32 -> 7589355 | F38: =F12+F26+F30+F31+F32 -> 6489355 | G38: =G12+G26+G30+G31+G32 -> 6489355 | H38: =H12+H26+H30+H31+H32 -> 34041775
B40: 予備費率 | C40: 0.15 | D40: 推奨予算 = 合計 × (1 + 予備費率)
B41: A. 予備費込み（推奨予算） | H41: =H35*(1+$C$40) -> 37425916
B42: B. 予備費込み（推奨予算） | H42: =H36*(1+$C$40) -> 38058416
B43: C. 予備費込み（推奨予算） | H43: =H37*(1+$C$40) -> 36934291
B44: D. 予備費込み（推奨予算） | H44: =H38*(1+$C$40) -> 39148041

Sheet 運用費_AWS_月別
A1: 運用費（AWS）— 月別・サービス別（USD）。最下段に円換算と人件費。運用開始を 1 か月目とし、切替月以降は中規模の数量を使用。
A2: 数量（小規模 / 中規模）は黄色セルで変更可。月額 = 単価 × 数量 × 稼働時間（固定費項目は月額 USD を直接入力）。
A4: 区分 | B4: サービス | C4: 計算 | D4: 数量 小規模 | E4: 数量 中規模 | F4: 単位 | G4: 1か月目 | H4: 2か月目 | I4: 3か月目 | J4: 4か月目 | K4: 5か月目 | L4: 6か月目 | M4: 7か月目 | N4: 8か月目 | O4: 9か月目 | P4: 10か月目 | Q4: 11か月目 | R4: 12か月目 | S4: 13か月目 | T4: 14か月目 | U4: 15か月目 | V4: 16か月目 | W4: 17か月目 | X4: 18か月目 | Y4: 19か月目 | Z4: 20か月目 | AA4: 21か月目 | AB4: 22か月目 | AC4: 23か月目 | AD4: 24か月目 | AE4: 25か月目 | AF4: 26か月目 | AG4: 27か月目 | AH4: 28か月目 | AI4: 29か月目 | AJ4: 30か月目 | AK4: 31か月目 | AL4: 32か月目 | AM4: 33か月目 | AN4: 34か月目 | AO4: 35か月目 | AP4: 36か月目 | AQ4: 年 1 合計 | AR4: 年 2 合計 | AS4: 年 3 合計 | AT4: 3 年合計
A5: 本番環境
A6: コンピュート | B6: Backend: ECS Fargate（1 vCPU × 2GB / タスク） | C6: 台数 × (vCPU 単価 + 2 × メモリ単価) × 稼働時間 | D6: 2 | E6: 4 | F6: タスク | G6: =IF(1>=前提!$B$8,$E6,$D6)*(前提!$B$40*1+前提!$B$41*2)*前提!$B$6 -> 72.0802 | H6: =IF(2>=前提!$B$8,$E6,$D6)*(前提!$B$40*1+前提!$B$41*2)*前提!$B$6 -> 72.0802 | I6: =IF(3>=前提!$B$8,$E6,$D6)*(前提!$B$40*1+前提!$B$41*2)*前提!$B$6 -> 72.0802 | J6: =IF(4>=前提!$B$8,$E6,$D6)*(前提!$B$40*1+前提!$B$41*2)*前提!$B$6 -> 72.0802 | K6: =IF(5>=前提!$B$8,$E6,$D6)*(前提!$B$40*1+前提!$B$41*2)*前提!$B$6 -> 72.0802 | L6: =IF(6>=前提!$B$8,$E6,$D6)*(前提!$B$40*1+前提!$B$41*2)*前提!$B$6 -> 72.0802 | M6: =IF(7>=前提!$B$8,$E6,$D6)*(前提!$B$40*1+前提!$B$41*2)*前提!$B$6 -> 72.0802 | N6: =IF(8>=前提!$B$8,$E6,$D6)*(前提!$B$40*1+前提!$B$41*2)*前提!$B$6 -> 72.0802 | O6: =IF(9>=前提!$B$8,$E6,$D6)*(前提!$B$40*1+前提!$B$41*2)*前提!$B$6 -> 72.0802 | P6: =IF(10>=前提!$B$8,$E6,$D6)*(前提!$B$40*1+前提!$B$41*2)*前提!$B$6 -> 72.0802 | Q6: =IF(11>=前提!$B$8,$E6,$D6)*(前提!$B$40*1+前提!$B$41*2)*前提!$B$6 -> 72.0802 | R6: =IF(12>=前提!$B$8,$E6,$D6)*(前提!$B$40*1+前提!$B$41*2)*前提!$B$6 -> 72.0802 | S6: =IF(13>=前提!$B$8,$E6,$D6)*(前提!$B$40*1+前提!$B$41*2)*前提!$B$6 -> 144.1604 | T6: =IF(14>=前提!$B$8,$E6,$D6)*(前提!$B$40*1+前提!$B$41*2)*前提!$B$6 -> 144.1604 | U6: =IF(15>=前提!$B$8,$E6,$D6)*(前提!$B$40*1+前提!$B$41*2)*前提!$B$6 -> 144.1604 | V6: =IF(16>=前提!$B$8,$E6,$D6)*(前提!$B$40*1+前提!$B$41*2)*前提!$B$6 -> 144.1604 | W6: =IF(17>=前提!$B$8,$E6,$D6)*(前提!$B$40*1+前提!$B$41*2)*前提!$B$6 -> 144.1604 | X6: =IF(18>=前提!$B$8,$E6,$D6)*(前提!$B$40*1+前提!$B$41*2)*前提!$B$6 -> 144.1604 | Y6: =IF(19>=前提!$B$8,$E6,$D6)*(前提!$B$40*1+前提!$B$41*2)*前提!$B$6 -> 144.1604 | Z6: =IF(20>=前提!$B$8,$E6,$D6)*(前提!$B$40*1+前提!$B$41*2)*前提!$B$6 -> 144.1604 | AA6: =IF(21>=前提!$B$8,$E6,$D6)*(前提!$B$40*1+前提!$B$41*2)*前提!$B$6 -> 144.1604 | AB6: =IF(22>=前提!$B$8,$E6,$D6)*(前提!$B$40*1+前提!$B$41*2)*前提!$B$6 -> 144.1604 | AC6: =IF(23>=前提!$B$8,$E6,$D6)*(前提!$B$40*1+前提!$B$41*2)*前提!$B$6 -> 144.1604 | AD6: =IF(24>=前提!$B$8,$E6,$D6)*(前提!$B$40*1+前提!$B$41*2)*前提!$B$6 -> 144.1604 | AE6: =IF(25>=前提!$B$8,$E6,$D6)*(前提!$B$40*1+前提!$B$41*2)*前提!$B$6 -> 144.1604 | AF6: =IF(26>=前提!$B$8,$E6,$D6)*(前提!$B$40*1+前提!$B$41*2)*前提!$B$6 -> 144.1604 | AG6: =IF(27>=前提!$B$8,$E6,$D6)*(前提!$B$40*1+前提!$B$41*2)*前提!$B$6 -> 144.1604 | AH6: =IF(28>=前提!$B$8,$E6,$D6)*(前提!$B$40*1+前提!$B$41*2)*前提!$B$6 -> 144.1604 | AI6: =IF(29>=前提!$B$8,$E6,$D6)*(前提!$B$40*1+前提!$B$41*2)*前提!$B$6 -> 144.1604 | AJ6: =IF(30>=前提!$B$8,$E6,$D6)*(前提!$B$40*1+前提!$B$41*2)*前提!$B$6 -> 144.1604 | AK6: =IF(31>=前提!$B$8,$E6,$D6)*(前提!$B$40*1+前提!$B$41*2)*前提!$B$6 -> 144.1604 | AL6: =IF(32>=前提!$B$8,$E6,$D6)*(前提!$B$40*1+前提!$B$41*2)*前提!$B$6 -> 144.1604 | AM6: =IF(33>=前提!$B$8,$E6,$D6)*(前提!$B$40*1+前提!$B$41*2)*前提!$B$6 -> 144.1604 | AN6: =IF(34>=前提!$B$8,$E6,$D6)*(前提!$B$40*1+前提!$B$41*2)*前提!$B$6 -> 144.1604 | AO6: =IF(35>=前提!$B$8,$E6,$D6)*(前提!$B$40*1+前提!$B$41*2)*前提!$B$6 -> 144.1604 | AP6: =IF(36>=前提!$B$8,$E6,$D6)*(前提!$B$40*1+前提!$B$41*2)*前提!$B$6 -> 144.1604 | AQ6: =SUM(G6:R6) -> 864.9624 | AR6: =SUM(S6:AD6) -> 1729.9248 | AS6: =SUM(AE6:AP6) -> 1729.9248 | AT6: =SUM(G6:AP6) -> 4324.812
A7: コンピュート | B7: Frontend: ECS Fargate（0.5 vCPU × 1GB / タスク） | C7: 台数 × (0.5 × vCPU 単価 + 1 × メモリ単価) × 稼働時間 | D7: 2 | E7: 4 | F7: タスク | G7: =IF(1>=前提!$B$8,$E7,$D7)*(前提!$B$40*0.5+前提!$B$41*1)*前提!$B$6 -> 36.0401 | H7: =IF(2>=前提!$B$8,$E7,$D7)*(前提!$B$40*0.5+前提!$B$41*1)*前提!$B$6 -> 36.0401 | I7: =IF(3>=前提!$B$8,$E7,$D7)*(前提!$B$40*0.5+前提!$B$41*1)*前提!$B$6 -> 36.0401 | J7: =IF(4>=前提!$B$8,$E7,$D7)*(前提!$B$40*0.5+前提!$B$41*1)*前提!$B$6 -> 36.0401 | K7: =IF(5>=前提!$B$8,$E7,$D7)*(前提!$B$40*0.5+前提!$B$41*1)*前提!$B$6 -> 36.0401 | L7: =IF(6>=前提!$B$8,$E7,$D7)*(前提!$B$40*0.5+前提!$B$41*1)*前提!$B$6 -> 36.0401 | M7: =IF(7>=前提!$B$8,$E7,$D7)*(前提!$B$40*0.5+前提!$B$41*1)*前提!$B$6 -> 36.0401 | N7: =IF(8>=前提!$B$8,$E7,$D7)*(前提!$B$40*0.5+前提!$B$41*1)*前提!$B$6 -> 36.0401 | O7: =IF(9>=前提!$B$8,$E7,$D7)*(前提!$B$40*0.5+前提!$B$41*1)*前提!$B$6 -> 36.0401 | P7: =IF(10>=前提!$B$8,$E7,$D7)*(前提!$B$40*0.5+前提!$B$41*1)*前提!$B$6 -> 36.0401 | Q7: =IF(11>=前提!$B$8,$E7,$D7)*(前提!$B$40*0.5+前提!$B$41*1)*前提!$B$6 -> 36.0401 | R7: =IF(12>=前提!$B$8,$E7,$D7)*(前提!$B$40*0.5+前提!$B$41*1)*前提!$B$6 -> 36.0401 | S7: =IF(13>=前提!$B$8,$E7,$D7)*(前提!$B$40*0.5+前提!$B$41*1)*前提!$B$6 -> 72.0802 | T7: =IF(14>=前提!$B$8,$E7,$D7)*(前提!$B$40*0.5+前提!$B$41*1)*前提!$B$6 -> 72.0802 | U7: =IF(15>=前提!$B$8,$E7,$D7)*(前提!$B$40*0.5+前提!$B$41*1)*前提!$B$6 -> 72.0802 | V7: =IF(16>=前提!$B$8,$E7,$D7)*(前提!$B$40*0.5+前提!$B$41*1)*前提!$B$6 -> 72.0802 | W7: =IF(17>=前提!$B$8,$E7,$D7)*(前提!$B$40*0.5+前提!$B$41*1)*前提!$B$6 -> 72.0802 | X7: =IF(18>=前提!$B$8,$E7,$D7)*(前提!$B$40*0.5+前提!$B$41*1)*前提!$B$6 -> 72.0802 | Y7: =IF(19>=前提!$B$8,$E7,$D7)*(前提!$B$40*0.5+前提!$B$41*1)*前提!$B$6 -> 72.0802 | Z7: =IF(20>=前提!$B$8,$E7,$D7)*(前提!$B$40*0.5+前提!$B$41*1)*前提!$B$6 -> 72.0802 | AA7: =IF(21>=前提!$B$8,$E7,$D7)*(前提!$B$40*0.5+前提!$B$41*1)*前提!$B$6 -> 72.0802 | AB7: =IF(22>=前提!$B$8,$E7,$D7)*(前提!$B$40*0.5+前提!$B$41*1)*前提!$B$6 -> 72.0802 | AC7: =IF(23>=前提!$B$8,$E7,$D7)*(前提!$B$40*0.5+前提!$B$41*1)*前提!$B$6 -> 72.0802 | AD7: =IF(24>=前提!$B$8,$E7,$D7)*(前提!$B$40*0.5+前提!$B$41*1)*前提!$B$6 -> 72.0802 | AE7: =IF(25>=前提!$B$8,$E7,$D7)*(前提!$B$40*0.5+前提!$B$41*1)*前提!$B$6 -> 72.0802 | AF7: =IF(26>=前提!$B$8,$E7,$D7)*(前提!$B$40*0.5+前提!$B$41*1)*前提!$B$6 -> 72.0802 | AG7: =IF(27>=前提!$B$8,$E7,$D7)*(前提!$B$40*0.5+前提!$B$41*1)*前提!$B$6 -> 72.0802 | AH7: =IF(28>=前提!$B$8,$E7,$D7)*(前提!$B$40*0.5+前提!$B$41*1)*前提!$B$6 -> 72.0802 | AI7: =IF(29>=前提!$B$8,$E7,$D7)*(前提!$B$40*0.5+前提!$B$41*1)*前提!$B$6 -> 72.0802 | AJ7: =IF(30>=前提!$B$8,$E7,$D7)*(前提!$B$40*0.5+前提!$B$41*1)*前提!$B$6 -> 72.0802 | AK7: =IF(31>=前提!$B$8,$E7,$D7)*(前提!$B$40*0.5+前提!$B$41*1)*前提!$B$6 -> 72.0802 | AL7: =IF(32>=前提!$B$8,$E7,$D7)*(前提!$B$40*0.5+前提!$B$41*1)*前提!$B$6 -> 72.0802 | AM7: =IF(33>=前提!$B$8,$E7,$D7)*(前提!$B$40*0.5+前提!$B$41*1)*前提!$B$6 -> 72.0802 | AN7: =IF(34>=前提!$B$8,$E7,$D7)*(前提!$B$40*0.5+前提!$B$41*1)*前提!$B$6 -> 72.0802 | AO7: =IF(35>=前提!$B$8,$E7,$D7)*(前提!$B$40*0.5+前提!$B$41*1)*前提!$B$6 -> 72.0802 | AP7: =IF(36>=前提!$B$8,$E7,$D7)*(前提!$B$40*0.5+前提!$B$41*1)*前提!$B$6 -> 72.0802 | AQ7: =SUM(G7:R7) -> 432.4812 | AR7: =SUM(S7:AD7) -> 864.9624 | AS7: =SUM(AE7:AP7) -> 864.9624 | AT7: =SUM(G7:AP7) -> 2162.406
A8: ネットワーク | B8: Application Load Balancer 固定費 | C8: 台数 × 時間単価 × 稼働時間 | D8: 1 | E8: 1 | F8: 台 | G8: =IF(1>=前提!$B$8,$E8,$D8)*前提!$B$42*前提!$B$6 -> 16.425 | H8: =IF(2>=前提!$B$8,$E8,$D8)*前提!$B$42*前提!$B$6 -> 16.425 | I8: =IF(3>=前提!$B$8,$E8,$D8)*前提!$B$42*前提!$B$6 -> 16.425 | J8: =IF(4>=前提!$B$8,$E8,$D8)*前提!$B$42*前提!$B$6 -> 16.425 | K8: =IF(5>=前提!$B$8,$E8,$D8)*前提!$B$42*前提!$B$6 -> 16.425 | L8: =IF(6>=前提!$B$8,$E8,$D8)*前提!$B$42*前提!$B$6 -> 16.425 | M8: =IF(7>=前提!$B$8,$E8,$D8)*前提!$B$42*前提!$B$6 -> 16.425 | N8: =IF(8>=前提!$B$8,$E8,$D8)*前提!$B$42*前提!$B$6 -> 16.425 | O8: =IF(9>=前提!$B$8,$E8,$D8)*前提!$B$42*前提!$B$6 -> 16.425 | P8: =IF(10>=前提!$B$8,$E8,$D8)*前提!$B$42*前提!$B$6 -> 16.425 | Q8: =IF(11>=前提!$B$8,$E8,$D8)*前提!$B$42*前提!$B$6 -> 16.425 | R8: =IF(12>=前提!$B$8,$E8,$D8)*前提!$B$42*前提!$B$6 -> 16.425 | S8: =IF(13>=前提!$B$8,$E8,$D8)*前提!$B$42*前提!$B$6 -> 16.425 | T8: =IF(14>=前提!$B$8,$E8,$D8)*前提!$B$42*前提!$B$6 -> 16.425 | U8: =IF(15>=前提!$B$8,$E8,$D8)*前提!$B$42*前提!$B$6 -> 16.425 | V8: =IF(16>=前提!$B$8,$E8,$D8)*前提!$B$42*前提!$B$6 -> 16.425 | W8: =IF(17>=前提!$B$8,$E8,$D8)*前提!$B$42*前提!$B$6 -> 16.425 | X8: =IF(18>=前提!$B$8,$E8,$D8)*前提!$B$42*前提!$B$6 -> 16.425 | Y8: =IF(19>=前提!$B$8,$E8,$D8)*前提!$B$42*前提!$B$6 -> 16.425 | Z8: =IF(20>=前提!$B$8,$E8,$D8)*前提!$B$42*前提!$B$6 -> 16.425 | AA8: =IF(21>=前提!$B$8,$E8,$D8)*前提!$B$42*前提!$B$6 -> 16.425 | AB8: =IF(22>=前提!$B$8,$E8,$D8)*前提!$B$42*前提!$B$6 -> 16.425 | AC8: =IF(23>=前提!$B$8,$E8,$D8)*前提!$B$42*前提!$B$6 -> 16.425 | AD8: =IF(24>=前提!$B$8,$E8,$D8)*前提!$B$42*前提!$B$6 -> 16.425 | AE8: =IF(25>=前提!$B$8,$E8,$D8)*前提!$B$42*前提!$B$6 -> 16.425 | AF8: =IF(26>=前提!$B$8,$E8,$D8)*前提!$B$42*前提!$B$6 -> 16.425 | AG8: =IF(27>=前提!$B$8,$E8,$D8)*前提!$B$42*前提!$B$6 -> 16.425 | AH8: =IF(28>=前提!$B$8,$E8,$D8)*前提!$B$42*前提!$B$6 -> 16.425 | AI8: =IF(29>=前提!$B$8,$E8,$D8)*前提!$B$42*前提!$B$6 -> 16.425 | AJ8: =IF(30>=前提!$B$8,$E8,$D8)*前提!$B$42*前提!$B$6 -> 16.425 | AK8: =IF(31>=前提!$B$8,$E8,$D8)*前提!$B$42*前提!$B$6 -> 16.425 | AL8: =IF(32>=前提!$B$8,$E8,$D8)*前提!$B$42*前提!$B$6 -> 16.425 | AM8: =IF(33>=前提!$B$8,$E8,$D8)*前提!$B$42*前提!$B$6 -> 16.425 | AN8: =IF(34>=前提!$B$8,$E8,$D8)*前提!$B$42*前提!$B$6 -> 16.425 | AO8: =IF(35>=前提!$B$8,$E8,$D8)*前提!$B$42*前提!$B$6 -> 16.425 | AP8: =IF(36>=前提!$B$8,$E8,$D8)*前提!$B$42*前提!$B$6 -> 16.425 | AQ8: =SUM(G8:R8) -> 197.1 | AR8: =SUM(S8:AD8) -> 197.1 | AS8: =SUM(AE8:AP8) -> 197.1 | AT8: =SUM(G8:AP8) -> 591.3
A9: ネットワーク | B9: ALB LCU（トラフィック従量） | C9: 月額（見積） | D9: 5 | E9: 25 | F9: USD/月 | G9: =IF(1>=前提!$B$8,$E9,$D9) -> 5 | H9: =IF(2>=前提!$B$8,$E9,$D9) -> 5 | I9: =IF(3>=前提!$B$8,$E9,$D9) -> 5 | J9: =IF(4>=前提!$B$8,$E9,$D9) -> 5 | K9: =IF(5>=前提!$B$8,$E9,$D9) -> 5 | L9: =IF(6>=前提!$B$8,$E9,$D9) -> 5 | M9: =IF(7>=前提!$B$8,$E9,$D9) -> 5 | N9: =IF(8>=前提!$B$8,$E9,$D9) -> 5 | O9: =IF(9>=前提!$B$8,$E9,$D9) -> 5 | P9: =IF(10>=前提!$B$8,$E9,$D9) -> 5 | Q9: =IF(11>=前提!$B$8,$E9,$D9) -> 5 | R9: =IF(12>=前提!$B$8,$E9,$D9) -> 5 | S9: =IF(13>=前提!$B$8,$E9,$D9) -> 25 | T9: =IF(14>=前提!$B$8,$E9,$D9) -> 25 | U9: =IF(15>=前提!$B$8,$E9,$D9) -> 25 | V9: =IF(16>=前提!$B$8,$E9,$D9) -> 25 | W9: =IF(17>=前提!$B$8,$E9,$D9) -> 25 | X9: =IF(18>=前提!$B$8,$E9,$D9) -> 25 | Y9: =IF(19>=前提!$B$8,$E9,$D9) -> 25 | Z9: =IF(20>=前提!$B$8,$E9,$D9) -> 25 | AA9: =IF(21>=前提!$B$8,$E9,$D9) -> 25 | AB9: =IF(22>=前提!$B$8,$E9,$D9) -> 25 | AC9: =IF(23>=前提!$B$8,$E9,$D9) -> 25 | AD9: =IF(24>=前提!$B$8,$E9,$D9) -> 25 | AE9: =IF(25>=前提!$B$8,$E9,$D9) -> 25 | AF9: =IF(26>=前提!$B$8,$E9,$D9) -> 25 | AG9: =IF(27>=前提!$B$8,$E9,$D9) -> 25 | AH9: =IF(28>=前提!$B$8,$E9,$D9) -> 25 | AI9: =IF(29>=前提!$B$8,$E9,$D9) -> 25 | AJ9: =IF(30>=前提!$B$8,$E9,$D9) -> 25 | AK9: =IF(31>=前提!$B$8,$E9,$D9) -> 25 | AL9: =IF(32>=前提!$B$8,$E9,$D9) -> 25 | AM9: =IF(33>=前提!$B$8,$E9,$D9) -> 25 | AN9: =IF(34>=前提!$B$8,$E9,$D9) -> 25 | AO9: =IF(35>=前提!$B$8,$E9,$D9) -> 25 | AP9: =IF(36>=前提!$B$8,$E9,$D9) -> 25 | AQ9: =SUM(G9:R9) -> 60 | AR9: =SUM(S9:AD9) -> 300 | AS9: =SUM(AE9:AP9) -> 300 | AT9: =SUM(G9:AP9) -> 660
A10: ネットワーク | B10: NAT Gateway | C10: 台数 × 時間単価 × 稼働時間 + データ処理 $3 | D10: 1 | E10: 2 | F10: 台 | G10: =IF(1>=前提!$B$8,$E10,$D10)*前提!$B$43*前提!$B$6+3 -> 35.85 | H10: =IF(2>=前提!$B$8,$E10,$D10)*前提!$B$43*前提!$B$6+3 -> 35.85 | I10: =IF(3>=前提!$B$8,$E10,$D10)*前提!$B$43*前提!$B$6+3 -> 35.85 | J10: =IF(4>=前提!$B$8,$E10,$D10)*前提!$B$43*前提!$B$6+3 -> 35.85 | K10: =IF(5>=前提!$B$8,$E10,$D10)*前提!$B$43*前提!$B$6+3 -> 35.85 | L10: =IF(6>=前提!$B$8,$E10,$D10)*前提!$B$43*前提!$B$6+3 -> 35.85 | M10: =IF(7>=前提!$B$8,$E10,$D10)*前提!$B$43*前提!$B$6+3 -> 35.85 | N10: =IF(8>=前提!$B$8,$E10,$D10)*前提!$B$43*前提!$B$6+3 -> 35.85 | O10: =IF(9>=前提!$B$8,$E10,$D10)*前提!$B$43*前提!$B$6+3 -> 35.85 | P10: =IF(10>=前提!$B$8,$E10,$D10)*前提!$B$43*前提!$B$6+3 -> 35.85 | Q10: =IF(11>=前提!$B$8,$E10,$D10)*前提!$B$43*前提!$B$6+3 -> 35.85 | R10: =IF(12>=前提!$B$8,$E10,$D10)*前提!$B$43*前提!$B$6+3 -> 35.85 | S10: =IF(13>=前提!$B$8,$E10,$D10)*前提!$B$43*前提!$B$6+3 -> 68.7 | T10: =IF(14>=前提!$B$8,$E10,$D10)*前提!$B$43*前提!$B$6+3 -> 68.7 | U10: =IF(15>=前提!$B$8,$E10,$D10)*前提!$B$43*前提!$B$6+3 -> 68.7 | V10: =IF(16>=前提!$B$8,$E10,$D10)*前提!$B$43*前提!$B$6+3 -> 68.7 | W10: =IF(17>=前提!$B$8,$E10,$D10)*前提!$B$43*前提!$B$6+3 -> 68.7 | X10: =IF(18>=前提!$B$8,$E10,$D10)*前提!$B$43*前提!$B$6+3 -> 68.7 | Y10: =IF(19>=前提!$B$8,$E10,$D10)*前提!$B$43*前提!$B$6+3 -> 68.7 | Z10: =IF(20>=前提!$B$8,$E10,$D10)*前提!$B$43*前提!$B$6+3 -> 68.7 | AA10: =IF(21>=前提!$B$8,$E10,$D10)*前提!$B$43*前提!$B$6+3 -> 68.7 | AB10: =IF(22>=前提!$B$8,$E10,$D10)*前提!$B$43*前提!$B$6+3 -> 68.7 | AC10: =IF(23>=前提!$B$8,$E10,$D10)*前提!$B$43*前提!$B$6+3 -> 68.7 | AD10: =IF(24>=前提!$B$8,$E10,$D10)*前提!$B$43*前提!$B$6+3 -> 68.7 | AE10: =IF(25>=前提!$B$8,$E10,$D10)*前提!$B$43*前提!$B$6+3 -> 68.7 | AF10: =IF(26>=前提!$B$8,$E10,$D10)*前提!$B$43*前提!$B$6+3 -> 68.7 | AG10: =IF(27>=前提!$B$8,$E10,$D10)*前提!$B$43*前提!$B$6+3 -> 68.7 | AH10: =IF(28>=前提!$B$8,$E10,$D10)*前提!$B$43*前提!$B$6+3 -> 68.7 | AI10: =IF(29>=前提!$B$8,$E10,$D10)*前提!$B$43*前提!$B$6+3 -> 68.7 | AJ10: =IF(30>=前提!$B$8,$E10,$D10)*前提!$B$43*前提!$B$6+3 -> 68.7 | AK10: =IF(31>=前提!$B$8,$E10,$D10)*前提!$B$43*前提!$B$6+3 -> 68.7 | AL10: =IF(32>=前提!$B$8,$E10,$D10)*前提!$B$43*前提!$B$6+3 -> 68.7 | AM10: =IF(33>=前提!$B$8,$E10,$D10)*前提!$B$43*前提!$B$6+3 -> 68.7 | AN10: =IF(34>=前提!$B$8,$E10,$D10)*前提!$B$43*前提!$B$6+3 -> 68.7 | AO10: =IF(35>=前提!$B$8,$E10,$D10)*前提!$B$43*前提!$B$6+3 -> 68.7 | AP10: =IF(36>=前提!$B$8,$E10,$D10)*前提!$B$43*前提!$B$6+3 -> 68.7 | AQ10: =SUM(G10:R10) -> 430.2 | AR10: =SUM(S10:AD10) -> 824.4 | AS10: =SUM(AE10:AP10) -> 824.4 | AT10: =SUM(G10:AP10) -> 2079
A11: データベース | B11: Neo4j AuraDB Professional（本番） | C11: GB × 単価 | D11: 2 | E11: 8 | F11: GB | G11: =IF(1>=前提!$B$8,$E11,$D11)*前提!$B$46 -> 131.4 | H11: =IF(2>=前提!$B$8,$E11,$D11)*前提!$B$46 -> 131.4 | I11: =IF(3>=前提!$B$8,$E11,$D11)*前提!$B$46 -> 131.4 | J11: =IF(4>=前提!$B$8,$E11,$D11)*前提!$B$46 -> 131.4 | K11: =IF(5>=前提!$B$8,$E11,$D11)*前提!$B$46 -> 131.4 | L11: =IF(6>=前提!$B$8,$E11,$D11)*前提!$B$46 -> 131.4 | M11: =IF(7>=前提!$B$8,$E11,$D11)*前提!$B$46 -> 131.4 | N11: =IF(8>=前提!$B$8,$E11,$D11)*前提!$B$46 -> 131.4 | O11: =IF(9>=前提!$B$8,$E11,$D11)*前提!$B$46 -> 131.4 | P11: =IF(10>=前提!$B$8,$E11,$D11)*前提!$B$46 -> 131.4 | Q11: =IF(11>=前提!$B$8,$E11,$D11)*前提!$B$46 -> 131.4 | R11: =IF(12>=前提!$B$8,$E11,$D11)*前提!$B$46 -> 131.4 | S11: =IF(13>=前提!$B$8,$E11,$D11)*前提!$B$46 -> 525.6 | T11: =IF(14>=前提!$B$8,$E11,$D11)*前提!$B$46 -> 525.6 | U11: =IF(15>=前提!$B$8,$E11,$D11)*前提!$B$46 -> 525.6 | V11: =IF(16>=前提!$B$8,$E11,$D11)*前提!$B$46 -> 525.6 | W11: =IF(17>=前提!$B$8,$E11,$D11)*前提!$B$46 -> 525.6 | X11: =IF(18>=前提!$B$8,$E11,$D11)*前提!$B$46 -> 525.6 | Y11: =IF(19>=前提!$B$8,$E11,$D11)*前提!$B$46 -> 525.6 | Z11: =IF(20>=前提!$B$8,$E11,$D11)*前提!$B$46 -> 525.6 | AA11: =IF(21>=前提!$B$8,$E11,$D11)*前提!$B$46 -> 525.6 | AB11: =IF(22>=前提!$B$8,$E11,$D11)*前提!$B$46 -> 525.6 | AC11: =IF(23>=前提!$B$8,$E11,$D11)*前提!$B$46 -> 525.6 | AD11: =IF(24>=前提!$B$8,$E11,$D11)*前提!$B$46 -> 525.6 | AE11: =IF(25>=前提!$B$8,$E11,$D11)*前提!$B$46 -> 525.6 | AF11: =IF(26>=前提!$B$8,$E11,$D11)*前提!$B$46 -> 525.6 | AG11: =IF(27>=前提!$B$8,$E11,$D11)*前提!$B$46 -> 525.6 | AH11: =IF(28>=前提!$B$8,$E11,$D11)*前提!$B$46 -> 525.6 | AI11: =IF(29>=前提!$B$8,$E11,$D11)*前提!$B$46 -> 525.6 | AJ11: =IF(30>=前提!$B$8,$E11,$D11)*前提!$B$46 -> 525.6 | AK11: =IF(31>=前提!$B$8,$E11,$D11)*前提!$B$46 -> 525.6 | AL11: =IF(32>=前提!$B$8,$E11,$D11)*前提!$B$46 -> 525.6 | AM11: =IF(33>=前提!$B$8,$E11,$D11)*前提!$B$46 -> 525.6 | AN11: =IF(34>=前提!$B$8,$E11,$D11)*前提!$B$46 -> 525.6 | AO11: =IF(35>=前提!$B$8,$E11,$D11)*前提!$B$46 -> 525.6 | AP11: =IF(36>=前提!$B$8,$E11,$D11)*前提!$B$46 -> 525.6 | AQ11: =SUM(G11:R11) -> 1576.8 | AR11: =SUM(S11:AD11) -> 6307.2 | AS11: =SUM(AE11:AP11) -> 6307.2 | AT11: =SUM(G11:AP11) -> 14191.2
A12: バッチ | B12: Collector: ECS Scheduled Task / Lambda + EventBridge | C12: 月額（見積） | D12: 5 | E12: 40 | F12: USD/月 | G12: =IF(1>=前提!$B$8,$E12,$D12) -> 5 | H12: =IF(2>=前提!$B$8,$E12,$D12) -> 5 | I12: =IF(3>=前提!$B$8,$E12,$D12) -> 5 | J12: =IF(4>=前提!$B$8,$E12,$D12) -> 5 | K12: =IF(5>=前提!$B$8,$E12,$D12) -> 5 | L12: =IF(6>=前提!$B$8,$E12,$D12) -> 5 | M12: =IF(7>=前提!$B$8,$E12,$D12) -> 5 | N12: =IF(8>=前提!$B$8,$E12,$D12) -> 5 | O12: =IF(9>=前提!$B$8,$E12,$D12) -> 5 | P12: =IF(10>=前提!$B$8,$E12,$D12) -> 5 | Q12: =IF(11>=前提!$B$8,$E12,$D12) -> 5 | R12: =IF(12>=前提!$B$8,$E12,$D12) -> 5 | S12: =IF(13>=前提!$B$8,$E12,$D12) -> 40 | T12: =IF(14>=前提!$B$8,$E12,$D12) -> 40 | U12: =IF(15>=前提!$B$8,$E12,$D12) -> 40 | V12: =IF(16>=前提!$B$8,$E12,$D12) -> 40 | W12: =IF(17>=前提!$B$8,$E12,$D12) -> 40 | X12: =IF(18>=前提!$B$8,$E12,$D12) -> 40 | Y12: =IF(19>=前提!$B$8,$E12,$D12) -> 40 | Z12: =IF(20>=前提!$B$8,$E12,$D12) -> 40 | AA12: =IF(21>=前提!$B$8,$E12,$D12) -> 40 | AB12: =IF(22>=前提!$B$8,$E12,$D12) -> 40 | AC12: =IF(23>=前提!$B$8,$E12,$D12) -> 40 | AD12: =IF(24>=前提!$B$8,$E12,$D12) -> 40 | AE12: =IF(25>=前提!$B$8,$E12,$D12) -> 40 | AF12: =IF(26>=前提!$B$8,$E12,$D12) -> 40 | AG12: =IF(27>=前提!$B$8,$E12,$D12) -> 40 | AH12: =IF(28>=前提!$B$8,$E12,$D12) -> 40 | AI12: =IF(29>=前提!$B$8,$E12,$D12) -> 40 | AJ12: =IF(30>=前提!$B$8,$E12,$D12) -> 40 | AK12: =IF(31>=前提!$B$8,$E12,$D12) -> 40 | AL12: =IF(32>=前提!$B$8,$E12,$D12) -> 40 | AM12: =IF(33>=前提!$B$8,$E12,$D12) -> 40 | AN12: =IF(34>=前提!$B$8,$E12,$D12) -> 40 | AO12: =IF(35>=前提!$B$8,$E12,$D12) -> 40 | AP12: =IF(36>=前提!$B$8,$E12,$D12) -> 40 | AQ12: =SUM(G12:R12) -> 60 | AR12: =SUM(S12:AD12) -> 480 | AS12: =SUM(AE12:AP12) -> 480 | AT12: =SUM(G12:AP12) -> 1020
A13: 運用基盤 | B13: CloudWatch Logs / Metrics / Alarms | C13: 月額（見積, 保持 30 日） | D13: 12 | E13: 60 | F13: USD/月 | G13: =IF(1>=前提!$B$8,$E13,$D13) -> 12 | H13: =IF(2>=前提!$B$8,$E13,$D13) -> 12 | I13: =IF(3>=前提!$B$8,$E13,$D13) -> 12 | J13: =IF(4>=前提!$B$8,$E13,$D13) -> 12 | K13: =IF(5>=前提!$B$8,$E13,$D13) -> 12 | L13: =IF(6>=前提!$B$8,$E13,$D13) -> 12 | M13: =IF(7>=前提!$B$8,$E13,$D13) -> 12 | N13: =IF(8>=前提!$B$8,$E13,$D13) -> 12 | O13: =IF(9>=前提!$B$8,$E13,$D13) -> 12 | P13: =IF(10>=前提!$B$8,$E13,$D13) -> 12 | Q13: =IF(11>=前提!$B$8,$E13,$D13) -> 12 | R13: =IF(12>=前提!$B$8,$E13,$D13) -> 12 | S13: =IF(13>=前提!$B$8,$E13,$D13) -> 60 | T13: =IF(14>=前提!$B$8,$E13,$D13) -> 60 | U13: =IF(15>=前提!$B$8,$E13,$D13) -> 60 | V13: =IF(16>=前提!$B$8,$E13,$D13) -> 60 | W13: =IF(17>=前提!$B$8,$E13,$D13) -> 60 | X13: =IF(18>=前提!$B$8,$E13,$D13) -> 60 | Y13: =IF(19>=前提!$B$8,$E13,$D13) -> 60 | Z13: =IF(20>=前提!$B$8,$E13,$D13) -> 60 | AA13: =IF(21>=前提!$B$8,$E13,$D13) -> 60 | AB13: =IF(22>=前提!$B$8,$E13,$D13) -> 60 | AC13: =IF(23>=前提!$B$8,$E13,$D13) -> 60 | AD13: =IF(24>=前提!$B$8,$E13,$D13) -> 60 | AE13: =IF(25>=前提!$B$8,$E13,$D13) -> 60 | AF13: =IF(26>=前提!$B$8,$E13,$D13) -> 60 | AG13: =IF(27>=前提!$B$8,$E13,$D13) -> 60 | AH13: =IF(28>=前提!$B$8,$E13,$D13) -> 60 | AI13: =IF(29>=前提!$B$8,$E13,$D13) -> 60 | AJ13: =IF(30>=前提!$B$8,$E13,$D13) -> 60 | AK13: =IF(31>=前提!$B$8,$E13,$D13) -> 60 | AL13: =IF(32>=前提!$B$8,$E13,$D13) -> 60 | AM13: =IF(33>=前提!$B$8,$E13,$D13) -> 60 | AN13: =IF(34>=前提!$B$8,$E13,$D13) -> 60 | AO13: =IF(35>=前提!$B$8,$E13,$D13) -> 60 | AP13: =IF(36>=前提!$B$8,$E13,$D13) -> 60 | AQ13: =SUM(G13:R13) -> 144 | AR13: =SUM(S13:AD13) -> 720 | AS13: =SUM(AE13:AP13) -> 720 | AT13: =SUM(G13:AP13) -> 1584
A14: 運用基盤 | B14: Cognito（認証） | C14: 月額（50 名まで無料枠） | D14: 0 | E14: 30 | F14: USD/月 | G14: =IF(1>=前提!$B$8,$E14,$D14) -> 0 | H14: =IF(2>=前提!$B$8,$E14,$D14) -> 0 | I14: =IF(3>=前提!$B$8,$E14,$D14) -> 0 | J14: =IF(4>=前提!$B$8,$E14,$D14) -> 0 | K14: =IF(5>=前提!$B$8,$E14,$D14) -> 0 | L14: =IF(6>=前提!$B$8,$E14,$D14) -> 0 | M14: =IF(7>=前提!$B$8,$E14,$D14) -> 0 | N14: =IF(8>=前提!$B$8,$E14,$D14) -> 0 | O14: =IF(9>=前提!$B$8,$E14,$D14) -> 0 | P14: =IF(10>=前提!$B$8,$E14,$D14) -> 0 | Q14: =IF(11>=前提!$B$8,$E14,$D14) -> 0 | R14: =IF(12>=前提!$B$8,$E14,$D14) -> 0 | S14: =IF(13>=前提!$B$8,$E14,$D14) -> 30 | T14: =IF(14>=前提!$B$8,$E14,$D14) -> 30 | U14: =IF(15>=前提!$B$8,$E14,$D14) -> 30 | V14: =IF(16>=前提!$B$8,$E14,$D14) -> 30 | W14: =IF(17>=前提!$B$8,$E14,$D14) -> 30 | X14: =IF(18>=前提!$B$8,$E14,$D14) -> 30 | Y14: =IF(19>=前提!$B$8,$E14,$D14) -> 30 | Z14: =IF(20>=前提!$B$8,$E14,$D14) -> 30 | AA14: =IF(21>=前提!$B$8,$E14,$D14) -> 30 | AB14: =IF(22>=前提!$B$8,$E14,$D14) -> 30 | AC14: =IF(23>=前提!$B$8,$E14,$D14) -> 30 | AD14: =IF(24>=前提!$B$8,$E14,$D14) -> 30 | AE14: =IF(25>=前提!$B$8,$E14,$D14) -> 30 | AF14: =IF(26>=前提!$B$8,$E14,$D14) -> 30 | AG14: =IF(27>=前提!$B$8,$E14,$D14) -> 30 | AH14: =IF(28>=前提!$B$8,$E14,$D14) -> 30 | AI14: =IF(29>=前提!$B$8,$E14,$D14) -> 30 | AJ14: =IF(30>=前提!$B$8,$E14,$D14) -> 30 | AK14: =IF(31>=前提!$B$8,$E14,$D14) -> 30 | AL14: =IF(32>=前提!$B$8,$E14,$D14) -> 30 | AM14: =IF(33>=前提!$B$8,$E14,$D14) -> 30 | AN14: =IF(34>=前提!$B$8,$E14,$D14) -> 30 | AO14: =IF(35>=前提!$B$8,$E14,$D14) -> 30 | AP14: =IF(36>=前提!$B$8,$E14,$D14) -> 30 | AQ14: =SUM(G14:R14) -> 0 | AR14: =SUM(S14:AD14) -> 360 | AS14: =SUM(AE14:AP14) -> 360 | AT14: =SUM(G14:AP14) -> 720
A15: 運用基盤 | B15: Secrets Manager / ECR / Route 53 | C15: 月額（見積） | D15: 5 | E15: 10 | F15: USD/月 | G15: =IF(1>=前提!$B$8,$E15,$D15) -> 5 | H15: =IF(2>=前提!$B$8,$E15,$D15) -> 5 | I15: =IF(3>=前提!$B$8,$E15,$D15) -> 5 | J15: =IF(4>=前提!$B$8,$E15,$D15) -> 5 | K15: =IF(5>=前提!$B$8,$E15,$D15) -> 5 | L15: =IF(6>=前提!$B$8,$E15,$D15) -> 5 | M15: =IF(7>=前提!$B$8,$E15,$D15) -> 5 | N15: =IF(8>=前提!$B$8,$E15,$D15) -> 5 | O15: =IF(9>=前提!$B$8,$E15,$D15) -> 5 | P15: =IF(10>=前提!$B$8,$E15,$D15) -> 5 | Q15: =IF(11>=前提!$B$8,$E15,$D15) -> 5 | R15: =IF(12>=前提!$B$8,$E15,$D15) -> 5 | S15: =IF(13>=前提!$B$8,$E15,$D15) -> 10 | T15: =IF(14>=前提!$B$8,$E15,$D15) -> 10 | U15: =IF(15>=前提!$B$8,$E15,$D15) -> 10 | V15: =IF(16>=前提!$B$8,$E15,$D15) -> 10 | W15: =IF(17>=前提!$B$8,$E15,$D15) -> 10 | X15: =IF(18>=前提!$B$8,$E15,$D15) -> 10 | Y15: =IF(19>=前提!$B$8,$E15,$D15) -> 10 | Z15: =IF(20>=前提!$B$8,$E15,$D15) -> 10 | AA15: =IF(21>=前提!$B$8,$E15,$D15) -> 10 | AB15: =IF(22>=前提!$B$8,$E15,$D15) -> 10 | AC15: =IF(23>=前提!$B$8,$E15,$D15) -> 10 | AD15: =IF(24>=前提!$B$8,$E15,$D15) -> 10 | AE15: =IF(25>=前提!$B$8,$E15,$D15) -> 10 | AF15: =IF(26>=前提!$B$8,$E15,$D15) -> 10 | AG15: =IF(27>=前提!$B$8,$E15,$D15) -> 10 | AH15: =IF(28>=前提!$B$8,$E15,$D15) -> 10 | AI15: =IF(29>=前提!$B$8,$E15,$D15) -> 10 | AJ15: =IF(30>=前提!$B$8,$E15,$D15) -> 10 | AK15: =IF(31>=前提!$B$8,$E15,$D15) -> 10 | AL15: =IF(32>=前提!$B$8,$E15,$D15) -> 10 | AM15: =IF(33>=前提!$B$8,$E15,$D15) -> 10 | AN15: =IF(34>=前提!$B$8,$E15,$D15) -> 10 | AO15: =IF(35>=前提!$B$8,$E15,$D15) -> 10 | AP15: =IF(36>=前提!$B$8,$E15,$D15) -> 10 | AQ15: =SUM(G15:R15) -> 60 | AR15: =SUM(S15:AD15) -> 120 | AS15: =SUM(AE15:AP15) -> 120 | AT15: =SUM(G15:AP15) -> 300
A16: 運用基盤 | B16: バックアップ / S3（ログ・エクスポート） | C16: 月額（見積） | D16: 3 | E16: 15 | F16: USD/月 | G16: =IF(1>=前提!$B$8,$E16,$D16) -> 3 | H16: =IF(2>=前提!$B$8,$E16,$D16) -> 3 | I16: =IF(3>=前提!$B$8,$E16,$D16) -> 3 | J16: =IF(4>=前提!$B$8,$E16,$D16) -> 3 | K16: =IF(5>=前提!$B$8,$E16,$D16) -> 3 | L16: =IF(6>=前提!$B$8,$E16,$D16) -> 3 | M16: =IF(7>=前提!$B$8,$E16,$D16) -> 3 | N16: =IF(8>=前提!$B$8,$E16,$D16) -> 3 | O16: =IF(9>=前提!$B$8,$E16,$D16) -> 3 | P16: =IF(10>=前提!$B$8,$E16,$D16) -> 3 | Q16: =IF(11>=前提!$B$8,$E16,$D16) -> 3 | R16: =IF(12>=前提!$B$8,$E16,$D16) -> 3 | S16: =IF(13>=前提!$B$8,$E16,$D16) -> 15 | T16: =IF(14>=前提!$B$8,$E16,$D16) -> 15 | U16: =IF(15>=前提!$B$8,$E16,$D16) -> 15 | V16: =IF(16>=前提!$B$8,$E16,$D16) -> 15 | W16: =IF(17>=前提!$B$8,$E16,$D16) -> 15 | X16: =IF(18>=前提!$B$8,$E16,$D16) -> 15 | Y16: =IF(19>=前提!$B$8,$E16,$D16) -> 15 | Z16: =IF(20>=前提!$B$8,$E16,$D16) -> 15 | AA16: =IF(21>=前提!$B$8,$E16,$D16) -> 15 | AB16: =IF(22>=前提!$B$8,$E16,$D16) -> 15 | AC16: =IF(23>=前提!$B$8,$E16,$D16) -> 15 | AD16: =IF(24>=前提!$B$8,$E16,$D16) -> 15 | AE16: =IF(25>=前提!$B$8,$E16,$D16) -> 15 | AF16: =IF(26>=前提!$B$8,$E16,$D16) -> 15 | AG16: =IF(27>=前提!$B$8,$E16,$D16) -> 15 | AH16: =IF(28>=前提!$B$8,$E16,$D16) -> 15 | AI16: =IF(29>=前提!$B$8,$E16,$D16) -> 15 | AJ16: =IF(30>=前提!$B$8,$E16,$D16) -> 15 | AK16: =IF(31>=前提!$B$8,$E16,$D16) -> 15 | AL16: =IF(32>=前提!$B$8,$E16,$D16) -> 15 | AM16: =IF(33>=前提!$B$8,$E16,$D16) -> 15 | AN16: =IF(34>=前提!$B$8,$E16,$D16) -> 15 | AO16: =IF(35>=前提!$B$8,$E16,$D16) -> 15 | AP16: =IF(36>=前提!$B$8,$E16,$D16) -> 15 | AQ16: =SUM(G16:R16) -> 36 | AR16: =SUM(S16:AD16) -> 180 | AS16: =SUM(AE16:AP16) -> 180 | AT16: =SUM(G16:AP16) -> 396
A17: AI | B17: Amazon Bedrock（Claude Sonnet 5.5 / Opus 5.5） | C17: 月額（AI 活用 第 1 弾の試算） | D17: 32 | E17: 300 | F17: USD/月 | G17: =IF(1>=前提!$B$8,$E17,$D17) -> 32 | H17: =IF(2>=前提!$B$8,$E17,$D17) -> 32 | I17: =IF(3>=前提!$B$8,$E17,$D17) -> 32 | J17: =IF(4>=前提!$B$8,$E17,$D17) -> 32 | K17: =IF(5>=前提!$B$8,$E17,$D17) -> 32 | L17: =IF(6>=前提!$B$8,$E17,$D17) -> 32 | M17: =IF(7>=前提!$B$8,$E17,$D17) -> 32 | N17: =IF(8>=前提!$B$8,$E17,$D17) -> 32 | O17: =IF(9>=前提!$B$8,$E17,$D17) -> 32 | P17: =IF(10>=前提!$B$8,$E17,$D17) -> 32 | Q17: =IF(11>=前提!$B$8,$E17,$D17) -> 32 | R17: =IF(12>=前提!$B$8,$E17,$D17) -> 32 | S17: =IF(13>=前提!$B$8,$E17,$D17) -> 300 | T17: =IF(14>=前提!$B$8,$E17,$D17) -> 300 | U17: =IF(15>=前提!$B$8,$E17,$D17) -> 300 | V17: =IF(16>=前提!$B$8,$E17,$D17) -> 300 | W17: =IF(17>=前提!$B$8,$E17,$D17) -> 300 | X17: =IF(18>=前提!$B$8,$E17,$D17) -> 300 | Y17: =IF(19>=前提!$B$8,$E17,$D17) -> 300 | Z17: =IF(20>=前提!$B$8,$E17,$D17) -> 300 | AA17: =IF(21>=前提!$B$8,$E17,$D17) -> 300 | AB17: =IF(22>=前提!$B$8,$E17,$D17) -> 300 | AC17: =IF(23>=前提!$B$8,$E17,$D17) -> 300 | AD17: =IF(24>=前提!$B$8,$E17,$D17) -> 300 | AE17: =IF(25>=前提!$B$8,$E17,$D17) -> 300 | AF17: =IF(26>=前提!$B$8,$E17,$D17) -> 300 | AG17: =IF(27>=前提!$B$8,$E17,$D17) -> 300 | AH17: =IF(28>=前提!$B$8,$E17,$D17) -> 300 | AI17: =IF(29>=前提!$B$8,$E17,$D17) -> 300 | AJ17: =IF(30>=前提!$B$8,$E17,$D17) -> 300 | AK17: =IF(31>=前提!$B$8,$E17,$D17) -> 300 | AL17: =IF(32>=前提!$B$8,$E17,$D17) -> 300 | AM17: =IF(33>=前提!$B$8,$E17,$D17) -> 300 | AN17: =IF(34>=前提!$B$8,$E17,$D17) -> 300 | AO17: =IF(35>=前提!$B$8,$E17,$D17) -> 300 | AP17: =IF(36>=前提!$B$8,$E17,$D17) -> 300 | AQ17: =SUM(G17:R17) -> 384 | AR17: =SUM(S17:AD17) -> 3600 | AS17: =SUM(AE17:AP17) -> 3600 | AT17: =SUM(G17:AP17) -> 7584
B18: 本番 小計（USD） | G18: =SUM(G6:G17) -> 353.7953 | H18: =SUM(H6:H17) -> 353.7953 | I18: =SUM(I6:I17) -> 353.7953 | J18: =SUM(J6:J17) -> 353.7953 | K18: =SUM(K6:K17) -> 353.7953 | L18: =SUM(L6:L17) -> 353.7953 | M18: =SUM(M6:M17) -> 353.7953 | N18: =SUM(N6:N17) -> 353.7953 | ... AT18: =SUM(AT6:AT17) -> 35612.718
A20: ステージング環境
B21: コンピュート・ネットワーク・バッチ・運用基盤（本番比） | C21: (本番小計 − DB − AI) × ステージング比率 | G21: =(G18-G11-G17)*前提!$B$9 -> 76.15812 | H21: =(H18-H11-H17)*前提!$B$9 -> 76.15812 | I21: =(I18-I11-I17)*前提!$B$9 -> 76.15812 | J21: =(J18-J11-J17)*前提!$B$9 -> 76.15812 | K21: =(K18-K11-K17)*前提!$B$9 -> 76.15812 | L21: =(L18-L11-L17)*前提!$B$9 -> 76.15812 | M21: =(M18-M11-M17)*前提!$B$9 -> 76.15812 | N21: =(N18-N11-N17)*前提!$B$9 -> 76.15812 | ... AP21: =(AP18-AP11-AP17)*前提!$B$9 -> 192.54624 | AQ21: =SUM(G21:R21) -> 913.89744 | AR21: =SUM(S21:AD21) -> 2310.5549 | AS21: =SUM(AE21:AP21) -> 2310.5549 | AT21: =SUM(G21:AP21) -> 5535.0072
B22: Neo4j AuraDB Professional（ステージング） | C22: GB × 単価 | D22: 1 | E22: 2 | F22: GB | G22: =IF(1>=前提!$B$8,$E22,$D22)*前提!$B$46 -> 65.7 | H22: =IF(2>=前提!$B$8,$E22,$D22)*前提!$B$46 -> 65.7 | I22: =IF(3>=前提!$B$8,$E22,$D22)*前提!$B$46 -> 65.7 | J22: =IF(4>=前提!$B$8,$E22,$D22)*前提!$B$46 -> 65.7 | K22: =IF(5>=前提!$B$8,$E22,$D22)*前提!$B$46 -> 65.7 | L22: =IF(6>=前提!$B$8,$E22,$D22)*前提!$B$46 -> 65.7 | M22: =IF(7>=前提!$B$8,$E22,$D22)*前提!$B$46 -> 65.7 | N22: =IF(8>=前提!$B$8,$E22,$D22)*前提!$B$46 -> 65.7 | O22: =IF(9>=前提!$B$8,$E22,$D22)*前提!$B$46 -> 65.7 | P22: =IF(10>=前提!$B$8,$E22,$D22)*前提!$B$46 -> 65.7 | Q22: =IF(11>=前提!$B$8,$E22,$D22)*前提!$B$46 -> 65.7 | R22: =IF(12>=前提!$B$8,$E22,$D22)*前提!$B$46 -> 65.7 | S22: =IF(13>=前提!$B$8,$E22,$D22)*前提!$B$46 -> 131.4 | T22: =IF(14>=前提!$B$8,$E22,$D22)*前提!$B$46 -> 131.4 | U22: =IF(15>=前提!$B$8,$E22,$D22)*前提!$B$46 -> 131.4 | V22: =IF(16>=前提!$B$8,$E22,$D22)*前提!$B$46 -> 131.4 | W22: =IF(17>=前提!$B$8,$E22,$D22)*前提!$B$46 -> 131.4 | X22: =IF(18>=前提!$B$8,$E22,$D22)*前提!$B$46 -> 131.4 | Y22: =IF(19>=前提!$B$8,$E22,$D22)*前提!$B$46 -> 131.4 | Z22: =IF(20>=前提!$B$8,$E22,$D22)*前提!$B$46 -> 131.4 | AA22: =IF(21>=前提!$B$8,$E22,$D22)*前提!$B$46 -> 131.4 | AB22: =IF(22>=前提!$B$8,$E22,$D22)*前提!$B$46 -> 131.4 | AC22: =IF(23>=前提!$B$8,$E22,$D22)*前提!$B$46 -> 131.4 | AD22: =IF(24>=前提!$B$8,$E22,$D22)*前提!$B$46 -> 131.4 | AE22: =IF(25>=前提!$B$8,$E22,$D22)*前提!$B$46 -> 131.4 | AF22: =IF(26>=前提!$B$8,$E22,$D22)*前提!$B$46 -> 131.4 | AG22: =IF(27>=前提!$B$8,$E22,$D22)*前提!$B$46 -> 131.4 | AH22: =IF(28>=前提!$B$8,$E22,$D22)*前提!$B$46 -> 131.4 | AI22: =IF(29>=前提!$B$8,$E22,$D22)*前提!$B$46 -> 131.4 | AJ22: =IF(30>=前提!$B$8,$E22,$D22)*前提!$B$46 -> 131.4 | AK22: =IF(31>=前提!$B$8,$E22,$D22)*前提!$B$46 -> 131.4 | AL22: =IF(32>=前提!$B$8,$E22,$D22)*前提!$B$46 -> 131.4 | AM22: =IF(33>=前提!$B$8,$E22,$D22)*前提!$B$46 -> 131.4 | AN22: =IF(34>=前提!$B$8,$E22,$D22)*前提!$B$46 -> 131.4 | AO22: =IF(35>=前提!$B$8,$E22,$D22)*前提!$B$46 -> 131.4 | AP22: =IF(36>=前提!$B$8,$E22,$D22)*前提!$B$46 -> 131.4 | AQ22: =SUM(G22:R22) -> 788.4 | AR22: =SUM(S22:AD22) -> 1576.8 | AS22: =SUM(AE22:AP22) -> 1576.8 | AT22: =SUM(G22:AP22) -> 3942
B23: ステージング 小計（USD） | G23: =G21+G22 -> 141.85812 | H23: =H21+H22 -> 141.85812 | I23: =I21+I22 -> 141.85812 | J23: =J21+J22 -> 141.85812 | K23: =K21+K22 -> 141.85812 | L23: =L21+L22 -> 141.85812 | M23: =M21+M22 -> 141.85812 | N23: =N21+N22 -> 141.85812 | ... AT23: =AT21+AT22 -> 9477.0072
B25: クラウド合計（USD） | G25: =G18+G23 -> 495.65342 | H25: =H18+H23 -> 495.65342 | I25: =I18+I23 -> 495.65342 | J25: =J18+J23 -> 495.65342 | K25: =K18+K23 -> 495.65342 | L25: =L18+L23 -> 495.65342 | M25: =M18+M23 -> 495.65342 | N25: =N18+N23 -> 495.65342 | ... AT25: =AT18+AT23 -> 45089.725
B26: クラウド合計（円） | G26: =G25*前提!$B$5 -> 74348.013 | H26: =H25*前提!$B$5 -> 74348.013 | I26: =I25*前提!$B$5 -> 74348.013 | J26: =J25*前提!$B$5 -> 74348.013 | K26: =K25*前提!$B$5 -> 74348.013 | L26: =L25*前提!$B$5 -> 74348.013 | M26: =M25*前提!$B$5 -> 74348.013 | N26: =N25*前提!$B$5 -> 74348.013 | ... AT26: =AT25*前提!$B$5 -> 6763458.8
B27: 保守・運用の人件費（円） | C27: 人月 × 単価（前提） | G27: =前提!$B$10*前提!$B$11 -> 805000 | H27: =前提!$B$10*前提!$B$11 -> 805000 | I27: =前提!$B$10*前提!$B$11 -> 805000 | J27: =前提!$B$10*前提!$B$11 -> 805000 | K27: =前提!$B$10*前提!$B$11 -> 805000 | L27: =前提!$B$10*前提!$B$11 -> 805000 | M27: =前提!$B$10*前提!$B$11 -> 805000 | N27: =前提!$B$10*前提!$B$11 -> 805000 | ... AP27: =前提!$B$10*前提!$B$11 -> 805000 | AQ27: =SUM(G27:R27) -> 9660000 | AR27: =SUM(S27:AD27) -> 9660000 | AS27: =SUM(AE27:AP27) -> 9660000 | AT27: =SUM(G27:AP27) -> 28980000
B28: 運用費 総合計（円） | G28: =G26+G27 -> 879348.01 | H28: =H26+H27 -> 879348.01 | I28: =I26+I27 -> 879348.01 | J28: =J26+J27 -> 879348.01 | K28: =K26+K27 -> 879348.01 | L28: =L26+L27 -> 879348.01 | M28: =M26+M27 -> 879348.01 | N28: =N26+N27 -> 879348.01 | ... AT28: =AT26+AT27 -> 35743459

Sheet 運用費_GCP_月別
A1: 運用費（GCP）— 月別・サービス別（USD）。最下段に円換算と人件費。運用開始を 1 か月目とし、切替月以降は中規模の数量を使用。
A2: 数量（小規模 / 中規模）は黄色セルで変更可。月額 = 単価 × 数量 × 稼働時間（固定費項目は月額 USD を直接入力）。
A4: 区分 | B4: サービス | C4: 計算 | D4: 数量 小規模 | E4: 数量 中規模 | F4: 単位 | G4: 1か月目 | H4: 2か月目 | I4: 3か月目 | J4: 4か月目 | K4: 5か月目 | L4: 6か月目 | M4: 7か月目 | N4: 8か月目 | O4: 9か月目 | P4: 10か月目 | Q4: 11か月目 | R4: 12か月目 | S4: 13か月目 | T4: 14か月目 | U4: 15か月目 | V4: 16か月目 | W4: 17か月目 | X4: 18か月目 | Y4: 19か月目 | Z4: 20か月目 | AA4: 21か月目 | AB4: 22か月目 | AC4: 23か月目 | AD4: 24か月目 | AE4: 25か月目 | AF4: 26か月目 | AG4: 27か月目 | AH4: 28か月目 | AI4: 29か月目 | AJ4: 30か月目 | AK4: 31か月目 | AL4: 32か月目 | AM4: 33か月目 | AN4: 34か月目 | AO4: 35か月目 | AP4: 36か月目 | AQ4: 年 1 合計 | AR4: 年 2 合計 | AS4: 年 3 合計 | AT4: 3 年合計
A5: 本番環境
A6: コンピュート | B6: Backend: Cloud Run（1 vCPU × 2GiB, 常時割当） | C6: インスタンス × (vCPU 単価 + 2 × メモリ単価) × 稼働時間 × 3600 | D6: 1 | E6: 3 | F6: インスタンス | G6: =IF(1>=前提!$B$8,$E6,$D6)*(前提!$B$44*1+前提!$B$45*2)*前提!$B$6*3600 -> 57.816 | H6: =IF(2>=前提!$B$8,$E6,$D6)*(前提!$B$44*1+前提!$B$45*2)*前提!$B$6*3600 -> 57.816 | I6: =IF(3>=前提!$B$8,$E6,$D6)*(前提!$B$44*1+前提!$B$45*2)*前提!$B$6*3600 -> 57.816 | J6: =IF(4>=前提!$B$8,$E6,$D6)*(前提!$B$44*1+前提!$B$45*2)*前提!$B$6*3600 -> 57.816 | K6: =IF(5>=前提!$B$8,$E6,$D6)*(前提!$B$44*1+前提!$B$45*2)*前提!$B$6*3600 -> 57.816 | L6: =IF(6>=前提!$B$8,$E6,$D6)*(前提!$B$44*1+前提!$B$45*2)*前提!$B$6*3600 -> 57.816 | M6: =IF(7>=前提!$B$8,$E6,$D6)*(前提!$B$44*1+前提!$B$45*2)*前提!$B$6*3600 -> 57.816 | N6: =IF(8>=前提!$B$8,$E6,$D6)*(前提!$B$44*1+前提!$B$45*2)*前提!$B$6*3600 -> 57.816 | O6: =IF(9>=前提!$B$8,$E6,$D6)*(前提!$B$44*1+前提!$B$45*2)*前提!$B$6*3600 -> 57.816 | P6: =IF(10>=前提!$B$8,$E6,$D6)*(前提!$B$44*1+前提!$B$45*2)*前提!$B$6*3600 -> 57.816 | Q6: =IF(11>=前提!$B$8,$E6,$D6)*(前提!$B$44*1+前提!$B$45*2)*前提!$B$6*3600 -> 57.816 | R6: =IF(12>=前提!$B$8,$E6,$D6)*(前提!$B$44*1+前提!$B$45*2)*前提!$B$6*3600 -> 57.816 | S6: =IF(13>=前提!$B$8,$E6,$D6)*(前提!$B$44*1+前提!$B$45*2)*前提!$B$6*3600 -> 173.448 | T6: =IF(14>=前提!$B$8,$E6,$D6)*(前提!$B$44*1+前提!$B$45*2)*前提!$B$6*3600 -> 173.448 | U6: =IF(15>=前提!$B$8,$E6,$D6)*(前提!$B$44*1+前提!$B$45*2)*前提!$B$6*3600 -> 173.448 | V6: =IF(16>=前提!$B$8,$E6,$D6)*(前提!$B$44*1+前提!$B$45*2)*前提!$B$6*3600 -> 173.448 | W6: =IF(17>=前提!$B$8,$E6,$D6)*(前提!$B$44*1+前提!$B$45*2)*前提!$B$6*3600 -> 173.448 | X6: =IF(18>=前提!$B$8,$E6,$D6)*(前提!$B$44*1+前提!$B$45*2)*前提!$B$6*3600 -> 173.448 | Y6: =IF(19>=前提!$B$8,$E6,$D6)*(前提!$B$44*1+前提!$B$45*2)*前提!$B$6*3600 -> 173.448 | Z6: =IF(20>=前提!$B$8,$E6,$D6)*(前提!$B$44*1+前提!$B$45*2)*前提!$B$6*3600 -> 173.448 | AA6: =IF(21>=前提!$B$8,$E6,$D6)*(前提!$B$44*1+前提!$B$45*2)*前提!$B$6*3600 -> 173.448 | AB6: =IF(22>=前提!$B$8,$E6,$D6)*(前提!$B$44*1+前提!$B$45*2)*前提!$B$6*3600 -> 173.448 | AC6: =IF(23>=前提!$B$8,$E6,$D6)*(前提!$B$44*1+前提!$B$45*2)*前提!$B$6*3600 -> 173.448 | AD6: =IF(24>=前提!$B$8,$E6,$D6)*(前提!$B$44*1+前提!$B$45*2)*前提!$B$6*3600 -> 173.448 | AE6: =IF(25>=前提!$B$8,$E6,$D6)*(前提!$B$44*1+前提!$B$45*2)*前提!$B$6*3600 -> 173.448 | AF6: =IF(26>=前提!$B$8,$E6,$D6)*(前提!$B$44*1+前提!$B$45*2)*前提!$B$6*3600 -> 173.448 | AG6: =IF(27>=前提!$B$8,$E6,$D6)*(前提!$B$44*1+前提!$B$45*2)*前提!$B$6*3600 -> 173.448 | AH6: =IF(28>=前提!$B$8,$E6,$D6)*(前提!$B$44*1+前提!$B$45*2)*前提!$B$6*3600 -> 173.448 | AI6: =IF(29>=前提!$B$8,$E6,$D6)*(前提!$B$44*1+前提!$B$45*2)*前提!$B$6*3600 -> 173.448 | AJ6: =IF(30>=前提!$B$8,$E6,$D6)*(前提!$B$44*1+前提!$B$45*2)*前提!$B$6*3600 -> 173.448 | AK6: =IF(31>=前提!$B$8,$E6,$D6)*(前提!$B$44*1+前提!$B$45*2)*前提!$B$6*3600 -> 173.448 | AL6: =IF(32>=前提!$B$8,$E6,$D6)*(前提!$B$44*1+前提!$B$45*2)*前提!$B$6*3600 -> 173.448 | AM6: =IF(33>=前提!$B$8,$E6,$D6)*(前提!$B$44*1+前提!$B$45*2)*前提!$B$6*3600 -> 173.448 | AN6: =IF(34>=前提!$B$8,$E6,$D6)*(前提!$B$44*1+前提!$B$45*2)*前提!$B$6*3600 -> 173.448 | AO6: =IF(35>=前提!$B$8,$E6,$D6)*(前提!$B$44*1+前提!$B$45*2)*前提!$B$6*3600 -> 173.448 | AP6: =IF(36>=前提!$B$8,$E6,$D6)*(前提!$B$44*1+前提!$B$45*2)*前提!$B$6*3600 -> 173.448 | AQ6: =SUM(G6:R6) -> 693.792 | AR6: =SUM(S6:AD6) -> 2081.376 | AS6: =SUM(AE6:AP6) -> 2081.376 | AT6: =SUM(G6:AP6) -> 4856.544
A7: コンピュート | B7: Frontend: Cloud Run（1 vCPU × 0.5GiB, 常時割当） | C7: インスタンス × (vCPU 単価 + 0.5 × メモリ単価) × 稼働時間 × 3600 | D7: 1 | E7: 2 | F7: インスタンス | G7: =IF(1>=前提!$B$8,$E7,$D7)*(前提!$B$44*1+前提!$B$45*0.5)*前提!$B$6*3600 -> 49.932 | H7: =IF(2>=前提!$B$8,$E7,$D7)*(前提!$B$44*1+前提!$B$45*0.5)*前提!$B$6*3600 -> 49.932 | I7: =IF(3>=前提!$B$8,$E7,$D7)*(前提!$B$44*1+前提!$B$45*0.5)*前提!$B$6*3600 -> 49.932 | J7: =IF(4>=前提!$B$8,$E7,$D7)*(前提!$B$44*1+前提!$B$45*0.5)*前提!$B$6*3600 -> 49.932 | K7: =IF(5>=前提!$B$8,$E7,$D7)*(前提!$B$44*1+前提!$B$45*0.5)*前提!$B$6*3600 -> 49.932 | L7: =IF(6>=前提!$B$8,$E7,$D7)*(前提!$B$44*1+前提!$B$45*0.5)*前提!$B$6*3600 -> 49.932 | M7: =IF(7>=前提!$B$8,$E7,$D7)*(前提!$B$44*1+前提!$B$45*0.5)*前提!$B$6*3600 -> 49.932 | N7: =IF(8>=前提!$B$8,$E7,$D7)*(前提!$B$44*1+前提!$B$45*0.5)*前提!$B$6*3600 -> 49.932 | O7: =IF(9>=前提!$B$8,$E7,$D7)*(前提!$B$44*1+前提!$B$45*0.5)*前提!$B$6*3600 -> 49.932 | P7: =IF(10>=前提!$B$8,$E7,$D7)*(前提!$B$44*1+前提!$B$45*0.5)*前提!$B$6*3600 -> 49.932 | Q7: =IF(11>=前提!$B$8,$E7,$D7)*(前提!$B$44*1+前提!$B$45*0.5)*前提!$B$6*3600 -> 49.932 | R7: =IF(12>=前提!$B$8,$E7,$D7)*(前提!$B$44*1+前提!$B$45*0.5)*前提!$B$6*3600 -> 49.932 | S7: =IF(13>=前提!$B$8,$E7,$D7)*(前提!$B$44*1+前提!$B$45*0.5)*前提!$B$6*3600 -> 99.864 | T7: =IF(14>=前提!$B$8,$E7,$D7)*(前提!$B$44*1+前提!$B$45*0.5)*前提!$B$6*3600 -> 99.864 | U7: =IF(15>=前提!$B$8,$E7,$D7)*(前提!$B$44*1+前提!$B$45*0.5)*前提!$B$6*3600 -> 99.864 | V7: =IF(16>=前提!$B$8,$E7,$D7)*(前提!$B$44*1+前提!$B$45*0.5)*前提!$B$6*3600 -> 99.864 | W7: =IF(17>=前提!$B$8,$E7,$D7)*(前提!$B$44*1+前提!$B$45*0.5)*前提!$B$6*3600 -> 99.864 | X7: =IF(18>=前提!$B$8,$E7,$D7)*(前提!$B$44*1+前提!$B$45*0.5)*前提!$B$6*3600 -> 99.864 | Y7: =IF(19>=前提!$B$8,$E7,$D7)*(前提!$B$44*1+前提!$B$45*0.5)*前提!$B$6*3600 -> 99.864 | Z7: =IF(20>=前提!$B$8,$E7,$D7)*(前提!$B$44*1+前提!$B$45*0.5)*前提!$B$6*3600 -> 99.864 | AA7: =IF(21>=前提!$B$8,$E7,$D7)*(前提!$B$44*1+前提!$B$45*0.5)*前提!$B$6*3600 -> 99.864 | AB7: =IF(22>=前提!$B$8,$E7,$D7)*(前提!$B$44*1+前提!$B$45*0.5)*前提!$B$6*3600 -> 99.864 | AC7: =IF(23>=前提!$B$8,$E7,$D7)*(前提!$B$44*1+前提!$B$45*0.5)*前提!$B$6*3600 -> 99.864 | AD7: =IF(24>=前提!$B$8,$E7,$D7)*(前提!$B$44*1+前提!$B$45*0.5)*前提!$B$6*3600 -> 99.864 | AE7: =IF(25>=前提!$B$8,$E7,$D7)*(前提!$B$44*1+前提!$B$45*0.5)*前提!$B$6*3600 -> 99.864 | AF7: =IF(26>=前提!$B$8,$E7,$D7)*(前提!$B$44*1+前提!$B$45*0.5)*前提!$B$6*3600 -> 99.864 | AG7: =IF(27>=前提!$B$8,$E7,$D7)*(前提!$B$44*1+前提!$B$45*0.5)*前提!$B$6*3600 -> 99.864 | AH7: =IF(28>=前提!$B$8,$E7,$D7)*(前提!$B$44*1+前提!$B$45*0.5)*前提!$B$6*3600 -> 99.864 | AI7: =IF(29>=前提!$B$8,$E7,$D7)*(前提!$B$44*1+前提!$B$45*0.5)*前提!$B$6*3600 -> 99.864 | AJ7: =IF(30>=前提!$B$8,$E7,$D7)*(前提!$B$44*1+前提!$B$45*0.5)*前提!$B$6*3600 -> 99.864 | AK7: =IF(31>=前提!$B$8,$E7,$D7)*(前提!$B$44*1+前提!$B$45*0.5)*前提!$B$6*3600 -> 99.864 | AL7: =IF(32>=前提!$B$8,$E7,$D7)*(前提!$B$44*1+前提!$B$45*0.5)*前提!$B$6*3600 -> 99.864 | AM7: =IF(33>=前提!$B$8,$E7,$D7)*(前提!$B$44*1+前提!$B$45*0.5)*前提!$B$6*3600 -> 99.864 | AN7: =IF(34>=前提!$B$8,$E7,$D7)*(前提!$B$44*1+前提!$B$45*0.5)*前提!$B$6*3600 -> 99.864 | AO7: =IF(35>=前提!$B$8,$E7,$D7)*(前提!$B$44*1+前提!$B$45*0.5)*前提!$B$6*3600 -> 99.864 | AP7: =IF(36>=前提!$B$8,$E7,$D7)*(前提!$B$44*1+前提!$B$45*0.5)*前提!$B$6*3600 -> 99.864 | AQ7: =SUM(G7:R7) -> 599.184 | AR7: =SUM(S7:AD7) -> 1198.368 | AS7: =SUM(AE7:AP7) -> 1198.368 | AT7: =SUM(G7:AP7) -> 2995.92
A8: ネットワーク | B8: External HTTPS Load Balancer（転送ルール + 転送量） | C8: 月額（見積） | D8: 18 | E8: 40 | F8: USD/月 | G8: =IF(1>=前提!$B$8,$E8,$D8) -> 18 | H8: =IF(2>=前提!$B$8,$E8,$D8) -> 18 | I8: =IF(3>=前提!$B$8,$E8,$D8) -> 18 | J8: =IF(4>=前提!$B$8,$E8,$D8) -> 18 | K8: =IF(5>=前提!$B$8,$E8,$D8) -> 18 | L8: =IF(6>=前提!$B$8,$E8,$D8) -> 18 | M8: =IF(7>=前提!$B$8,$E8,$D8) -> 18 | N8: =IF(8>=前提!$B$8,$E8,$D8) -> 18 | O8: =IF(9>=前提!$B$8,$E8,$D8) -> 18 | P8: =IF(10>=前提!$B$8,$E8,$D8) -> 18 | Q8: =IF(11>=前提!$B$8,$E8,$D8) -> 18 | R8: =IF(12>=前提!$B$8,$E8,$D8) -> 18 | S8: =IF(13>=前提!$B$8,$E8,$D8) -> 40 | T8: =IF(14>=前提!$B$8,$E8,$D8) -> 40 | U8: =IF(15>=前提!$B$8,$E8,$D8) -> 40 | V8: =IF(16>=前提!$B$8,$E8,$D8) -> 40 | W8: =IF(17>=前提!$B$8,$E8,$D8) -> 40 | X8: =IF(18>=前提!$B$8,$E8,$D8) -> 40 | Y8: =IF(19>=前提!$B$8,$E8,$D8) -> 40 | Z8: =IF(20>=前提!$B$8,$E8,$D8) -> 40 | AA8: =IF(21>=前提!$B$8,$E8,$D8) -> 40 | AB8: =IF(22>=前提!$B$8,$E8,$D8) -> 40 | AC8: =IF(23>=前提!$B$8,$E8,$D8) -> 40 | AD8: =IF(24>=前提!$B$8,$E8,$D8) -> 40 | AE8: =IF(25>=前提!$B$8,$E8,$D8) -> 40 | AF8: =IF(26>=前提!$B$8,$E8,$D8) -> 40 | AG8: =IF(27>=前提!$B$8,$E8,$D8) -> 40 | AH8: =IF(28>=前提!$B$8,$E8,$D8) -> 40 | AI8: =IF(29>=前提!$B$8,$E8,$D8) -> 40 | AJ8: =IF(30>=前提!$B$8,$E8,$D8) -> 40 | AK8: =IF(31>=前提!$B$8,$E8,$D8) -> 40 | AL8: =IF(32>=前提!$B$8,$E8,$D8) -> 40 | AM8: =IF(33>=前提!$B$8,$E8,$D8) -> 40 | AN8: =IF(34>=前提!$B$8,$E8,$D8) -> 40 | AO8: =IF(35>=前提!$B$8,$E8,$D8) -> 40 | AP8: =IF(36>=前提!$B$8,$E8,$D8) -> 40 | AQ8: =SUM(G8:R8) -> 216 | AR8: =SUM(S8:AD8) -> 480 | AS8: =SUM(AE8:AP8) -> 480 | AT8: =SUM(G8:AP8) -> 1176
A9: ネットワーク | B9: Serverless VPC Access コネクタ | C9: 月額（見積, 不要な構成も可） | D9: 15 | E9: 30 | F9: USD/月 | G9: =IF(1>=前提!$B$8,$E9,$D9) -> 15 | H9: =IF(2>=前提!$B$8,$E9,$D9) -> 15 | I9: =IF(3>=前提!$B$8,$E9,$D9) -> 15 | J9: =IF(4>=前提!$B$8,$E9,$D9) -> 15 | K9: =IF(5>=前提!$B$8,$E9,$D9) -> 15 | L9: =IF(6>=前提!$B$8,$E9,$D9) -> 15 | M9: =IF(7>=前提!$B$8,$E9,$D9) -> 15 | N9: =IF(8>=前提!$B$8,$E9,$D9) -> 15 | O9: =IF(9>=前提!$B$8,$E9,$D9) -> 15 | P9: =IF(10>=前提!$B$8,$E9,$D9) -> 15 | Q9: =IF(11>=前提!$B$8,$E9,$D9) -> 15 | R9: =IF(12>=前提!$B$8,$E9,$D9) -> 15 | S9: =IF(13>=前提!$B$8,$E9,$D9) -> 30 | T9: =IF(14>=前提!$B$8,$E9,$D9) -> 30 | U9: =IF(15>=前提!$B$8,$E9,$D9) -> 30 | V9: =IF(16>=前提!$B$8,$E9,$D9) -> 30 | W9: =IF(17>=前提!$B$8,$E9,$D9) -> 30 | X9: =IF(18>=前提!$B$8,$E9,$D9) -> 30 | Y9: =IF(19>=前提!$B$8,$E9,$D9) -> 30 | Z9: =IF(20>=前提!$B$8,$E9,$D9) -> 30 | AA9: =IF(21>=前提!$B$8,$E9,$D9) -> 30 | AB9: =IF(22>=前提!$B$8,$E9,$D9) -> 30 | AC9: =IF(23>=前提!$B$8,$E9,$D9) -> 30 | AD9: =IF(24>=前提!$B$8,$E9,$D9) -> 30 | AE9: =IF(25>=前提!$B$8,$E9,$D9) -> 30 | AF9: =IF(26>=前提!$B$8,$E9,$D9) -> 30 | AG9: =IF(27>=前提!$B$8,$E9,$D9) -> 30 | AH9: =IF(28>=前提!$B$8,$E9,$D9) -> 30 | AI9: =IF(29>=前提!$B$8,$E9,$D9) -> 30 | AJ9: =IF(30>=前提!$B$8,$E9,$D9) -> 30 | AK9: =IF(31>=前提!$B$8,$E9,$D9) -> 30 | AL9: =IF(32>=前提!$B$8,$E9,$D9) -> 30 | AM9: =IF(33>=前提!$B$8,$E9,$D9) -> 30 | AN9: =IF(34>=前提!$B$8,$E9,$D9) -> 30 | AO9: =IF(35>=前提!$B$8,$E9,$D9) -> 30 | AP9: =IF(36>=前提!$B$8,$E9,$D9) -> 30 | AQ9: =SUM(G9:R9) -> 180 | AR9: =SUM(S9:AD9) -> 360 | AS9: =SUM(AE9:AP9) -> 360 | AT9: =SUM(G9:AP9) -> 900
A10: データベース | B10: Neo4j AuraDB Professional（本番） | C10: GB × 単価 | D10: 2 | E10: 8 | F10: GB | G10: =IF(1>=前提!$B$8,$E10,$D10)*前提!$B$46 -> 131.4 | H10: =IF(2>=前提!$B$8,$E10,$D10)*前提!$B$46 -> 131.4 | I10: =IF(3>=前提!$B$8,$E10,$D10)*前提!$B$46 -> 131.4 | J10: =IF(4>=前提!$B$8,$E10,$D10)*前提!$B$46 -> 131.4 | K10: =IF(5>=前提!$B$8,$E10,$D10)*前提!$B$46 -> 131.4 | L10: =IF(6>=前提!$B$8,$E10,$D10)*前提!$B$46 -> 131.4 | M10: =IF(7>=前提!$B$8,$E10,$D10)*前提!$B$46 -> 131.4 | N10: =IF(8>=前提!$B$8,$E10,$D10)*前提!$B$46 -> 131.4 | O10: =IF(9>=前提!$B$8,$E10,$D10)*前提!$B$46 -> 131.4 | P10: =IF(10>=前提!$B$8,$E10,$D10)*前提!$B$46 -> 131.4 | Q10: =IF(11>=前提!$B$8,$E10,$D10)*前提!$B$46 -> 131.4 | R10: =IF(12>=前提!$B$8,$E10,$D10)*前提!$B$46 -> 131.4 | S10: =IF(13>=前提!$B$8,$E10,$D10)*前提!$B$46 -> 525.6 | T10: =IF(14>=前提!$B$8,$E10,$D10)*前提!$B$46 -> 525.6 | U10: =IF(15>=前提!$B$8,$E10,$D10)*前提!$B$46 -> 525.6 | V10: =IF(16>=前提!$B$8,$E10,$D10)*前提!$B$46 -> 525.6 | W10: =IF(17>=前提!$B$8,$E10,$D10)*前提!$B$46 -> 525.6 | X10: =IF(18>=前提!$B$8,$E10,$D10)*前提!$B$46 -> 525.6 | Y10: =IF(19>=前提!$B$8,$E10,$D10)*前提!$B$46 -> 525.6 | Z10: =IF(20>=前提!$B$8,$E10,$D10)*前提!$B$46 -> 525.6 | AA10: =IF(21>=前提!$B$8,$E10,$D10)*前提!$B$46 -> 525.6 | AB10: =IF(22>=前提!$B$8,$E10,$D10)*前提!$B$46 -> 525.6 | AC10: =IF(23>=前提!$B$8,$E10,$D10)*前提!$B$46 -> 525.6 | AD10: =IF(24>=前提!$B$8,$E10,$D10)*前提!$B$46 -> 525.6 | AE10: =IF(25>=前提!$B$8,$E10,$D10)*前提!$B$46 -> 525.6 | AF10: =IF(26>=前提!$B$8,$E10,$D10)*前提!$B$46 -> 525.6 | AG10: =IF(27>=前提!$B$8,$E10,$D10)*前提!$B$46 -> 525.6 | AH10: =IF(28>=前提!$B$8,$E10,$D10)*前提!$B$46 -> 525.6 | AI10: =IF(29>=前提!$B$8,$E10,$D10)*前提!$B$46 -> 525.6 | AJ10: =IF(30>=前提!$B$8,$E10,$D10)*前提!$B$46 -> 525.6 | AK10: =IF(31>=前提!$B$8,$E10,$D10)*前提!$B$46 -> 525.6 | AL10: =IF(32>=前提!$B$8,$E10,$D10)*前提!$B$46 -> 525.6 | AM10: =IF(33>=前提!$B$8,$E10,$D10)*前提!$B$46 -> 525.6 | AN10: =IF(34>=前提!$B$8,$E10,$D10)*前提!$B$46 -> 525.6 | AO10: =IF(35>=前提!$B$8,$E10,$D10)*前提!$B$46 -> 525.6 | AP10: =IF(36>=前提!$B$8,$E10,$D10)*前提!$B$46 -> 525.6 | AQ10: =SUM(G10:R10) -> 1576.8 | AR10: =SUM(S10:AD10) -> 6307.2 | AS10: =SUM(AE10:AP10) -> 6307.2 | AT10: =SUM(G10:AP10) -> 14191.2
A11: バッチ | B11: Collector: Cloud Run Jobs + Cloud Scheduler | C11: 月額（見積） | D11: 3 | E11: 30 | F11: USD/月 | G11: =IF(1>=前提!$B$8,$E11,$D11) -> 3 | H11: =IF(2>=前提!$B$8,$E11,$D11) -> 3 | I11: =IF(3>=前提!$B$8,$E11,$D11) -> 3 | J11: =IF(4>=前提!$B$8,$E11,$D11) -> 3 | K11: =IF(5>=前提!$B$8,$E11,$D11) -> 3 | L11: =IF(6>=前提!$B$8,$E11,$D11) -> 3 | M11: =IF(7>=前提!$B$8,$E11,$D11) -> 3 | N11: =IF(8>=前提!$B$8,$E11,$D11) -> 3 | O11: =IF(9>=前提!$B$8,$E11,$D11) -> 3 | P11: =IF(10>=前提!$B$8,$E11,$D11) -> 3 | Q11: =IF(11>=前提!$B$8,$E11,$D11) -> 3 | R11: =IF(12>=前提!$B$8,$E11,$D11) -> 3 | S11: =IF(13>=前提!$B$8,$E11,$D11) -> 30 | T11: =IF(14>=前提!$B$8,$E11,$D11) -> 30 | U11: =IF(15>=前提!$B$8,$E11,$D11) -> 30 | V11: =IF(16>=前提!$B$8,$E11,$D11) -> 30 | W11: =IF(17>=前提!$B$8,$E11,$D11) -> 30 | X11: =IF(18>=前提!$B$8,$E11,$D11) -> 30 | Y11: =IF(19>=前提!$B$8,$E11,$D11) -> 30 | Z11: =IF(20>=前提!$B$8,$E11,$D11) -> 30 | AA11: =IF(21>=前提!$B$8,$E11,$D11) -> 30 | AB11: =IF(22>=前提!$B$8,$E11,$D11) -> 30 | AC11: =IF(23>=前提!$B$8,$E11,$D11) -> 30 | AD11: =IF(24>=前提!$B$8,$E11,$D11) -> 30 | AE11: =IF(25>=前提!$B$8,$E11,$D11) -> 30 | AF11: =IF(26>=前提!$B$8,$E11,$D11) -> 30 | AG11: =IF(27>=前提!$B$8,$E11,$D11) -> 30 | AH11: =IF(28>=前提!$B$8,$E11,$D11) -> 30 | AI11: =IF(29>=前提!$B$8,$E11,$D11) -> 30 | AJ11: =IF(30>=前提!$B$8,$E11,$D11) -> 30 | AK11: =IF(31>=前提!$B$8,$E11,$D11) -> 30 | AL11: =IF(32>=前提!$B$8,$E11,$D11) -> 30 | AM11: =IF(33>=前提!$B$8,$E11,$D11) -> 30 | AN11: =IF(34>=前提!$B$8,$E11,$D11) -> 30 | AO11: =IF(35>=前提!$B$8,$E11,$D11) -> 30 | AP11: =IF(36>=前提!$B$8,$E11,$D11) -> 30 | AQ11: =SUM(G11:R11) -> 36 | AR11: =SUM(S11:AD11) -> 360 | AS11: =SUM(AE11:AP11) -> 360 | AT11: =SUM(G11:AP11) -> 756
A12: 運用基盤 | B12: Cloud Logging / Monitoring | C12: 月額（見積, 保持 30 日） | D12: 6 | E12: 40 | F12: USD/月 | G12: =IF(1>=前提!$B$8,$E12,$D12) -> 6 | H12: =IF(2>=前提!$B$8,$E12,$D12) -> 6 | I12: =IF(3>=前提!$B$8,$E12,$D12) -> 6 | J12: =IF(4>=前提!$B$8,$E12,$D12) -> 6 | K12: =IF(5>=前提!$B$8,$E12,$D12) -> 6 | L12: =IF(6>=前提!$B$8,$E12,$D12) -> 6 | M12: =IF(7>=前提!$B$8,$E12,$D12) -> 6 | N12: =IF(8>=前提!$B$8,$E12,$D12) -> 6 | O12: =IF(9>=前提!$B$8,$E12,$D12) -> 6 | P12: =IF(10>=前提!$B$8,$E12,$D12) -> 6 | Q12: =IF(11>=前提!$B$8,$E12,$D12) -> 6 | R12: =IF(12>=前提!$B$8,$E12,$D12) -> 6 | S12: =IF(13>=前提!$B$8,$E12,$D12) -> 40 | T12: =IF(14>=前提!$B$8,$E12,$D12) -> 40 | U12: =IF(15>=前提!$B$8,$E12,$D12) -> 40 | V12: =IF(16>=前提!$B$8,$E12,$D12) -> 40 | W12: =IF(17>=前提!$B$8,$E12,$D12) -> 40 | X12: =IF(18>=前提!$B$8,$E12,$D12) -> 40 | Y12: =IF(19>=前提!$B$8,$E12,$D12) -> 40 | Z12: =IF(20>=前提!$B$8,$E12,$D12) -> 40 | AA12: =IF(21>=前提!$B$8,$E12,$D12) -> 40 | AB12: =IF(22>=前提!$B$8,$E12,$D12) -> 40 | AC12: =IF(23>=前提!$B$8,$E12,$D12) -> 40 | AD12: =IF(24>=前提!$B$8,$E12,$D12) -> 40 | AE12: =IF(25>=前提!$B$8,$E12,$D12) -> 40 | AF12: =IF(26>=前提!$B$8,$E12,$D12) -> 40 | AG12: =IF(27>=前提!$B$8,$E12,$D12) -> 40 | AH12: =IF(28>=前提!$B$8,$E12,$D12) -> 40 | AI12: =IF(29>=前提!$B$8,$E12,$D12) -> 40 | AJ12: =IF(30>=前提!$B$8,$E12,$D12) -> 40 | AK12: =IF(31>=前提!$B$8,$E12,$D12) -> 40 | AL12: =IF(32>=前提!$B$8,$E12,$D12) -> 40 | AM12: =IF(33>=前提!$B$8,$E12,$D12) -> 40 | AN12: =IF(34>=前提!$B$8,$E12,$D12) -> 40 | AO12: =IF(35>=前提!$B$8,$E12,$D12) -> 40 | AP12: =IF(36>=前提!$B$8,$E12,$D12) -> 40 | AQ12: =SUM(G12:R12) -> 72 | AR12: =SUM(S12:AD12) -> 480 | AS12: =SUM(AE12:AP12) -> 480 | AT12: =SUM(G12:AP12) -> 1032
A13: 運用基盤 | B13: Identity-Aware Proxy（認証） | C13: 無料 | D13: 0 | E13: 0 | F13: USD/月 | G13: =IF(1>=前提!$B$8,$E13,$D13) -> 0 | H13: =IF(2>=前提!$B$8,$E13,$D13) -> 0 | I13: =IF(3>=前提!$B$8,$E13,$D13) -> 0 | J13: =IF(4>=前提!$B$8,$E13,$D13) -> 0 | K13: =IF(5>=前提!$B$8,$E13,$D13) -> 0 | L13: =IF(6>=前提!$B$8,$E13,$D13) -> 0 | M13: =IF(7>=前提!$B$8,$E13,$D13) -> 0 | N13: =IF(8>=前提!$B$8,$E13,$D13) -> 0 | O13: =IF(9>=前提!$B$8,$E13,$D13) -> 0 | P13: =IF(10>=前提!$B$8,$E13,$D13) -> 0 | Q13: =IF(11>=前提!$B$8,$E13,$D13) -> 0 | R13: =IF(12>=前提!$B$8,$E13,$D13) -> 0 | S13: =IF(13>=前提!$B$8,$E13,$D13) -> 0 | T13: =IF(14>=前提!$B$8,$E13,$D13) -> 0 | U13: =IF(15>=前提!$B$8,$E13,$D13) -> 0 | V13: =IF(16>=前提!$B$8,$E13,$D13) -> 0 | W13: =IF(17>=前提!$B$8,$E13,$D13) -> 0 | X13: =IF(18>=前提!$B$8,$E13,$D13) -> 0 | Y13: =IF(19>=前提!$B$8,$E13,$D13) -> 0 | Z13: =IF(20>=前提!$B$8,$E13,$D13) -> 0 | AA13: =IF(21>=前提!$B$8,$E13,$D13) -> 0 | AB13: =IF(22>=前提!$B$8,$E13,$D13) -> 0 | AC13: =IF(23>=前提!$B$8,$E13,$D13) -> 0 | AD13: =IF(24>=前提!$B$8,$E13,$D13) -> 0 | AE13: =IF(25>=前提!$B$8,$E13,$D13) -> 0 | AF13: =IF(26>=前提!$B$8,$E13,$D13) -> 0 | AG13: =IF(27>=前提!$B$8,$E13,$D13) -> 0 | AH13: =IF(28>=前提!$B$8,$E13,$D13) -> 0 | AI13: =IF(29>=前提!$B$8,$E13,$D13) -> 0 | AJ13: =IF(30>=前提!$B$8,$E13,$D13) -> 0 | AK13: =IF(31>=前提!$B$8,$E13,$D13) -> 0 | AL13: =IF(32>=前提!$B$8,$E13,$D13) -> 0 | AM13: =IF(33>=前提!$B$8,$E13,$D13) -> 0 | AN13: =IF(34>=前提!$B$8,$E13,$D13) -> 0 | AO13: =IF(35>=前提!$B$8,$E13,$D13) -> 0 | AP13: =IF(36>=前提!$B$8,$E13,$D13) -> 0 | AQ13: =SUM(G13:R13) -> 0 | AR13: =SUM(S13:AD13) -> 0 | AS13: =SUM(AE13:AP13) -> 0 | AT13: =SUM(G13:AP13) -> 0
